Workbook

Sheet Maliyet Talebi
A1: # | B1: Etsy ID | C1: Urun / Product | D1: Durum | E1: Form | F1: Genislik mm (cikarim) | G1: Shank mm | H1: Kalinlik mm | I1: Basliktaki mm | J1: KONTROL | K1: Tas (aciklamadan) | L1: GRAM 14K (US 7) | M1: ISCILIK USD | N1: TAS+MIHLAMA USD | O1: DOKUM+DIGER USD | P1: URETICI NOTU | Q1: Metal maliyeti USD | R1: TOPLAM MALIYET USD | S1: Bizim gram tahminimiz | T1: Etsy link
A2: 1 | B2: 4556227760 | C2: 11mm Dome Band Ring | Chunky Minimalist Statement Ring, Stacking Jewelry | D2: Pasif | E2: dome | F2: 11 | G2: 3.5 | H2: 1.5 | I2: 11 | K2: yok / none | Q2: =IF($L2="","",$L2*Varsayimlar!$B$5*(1+Varsayimlar!$B$7)) | R2: =IF($L2="","",$Q2+N($M2)+N($N2)+N($O2)) | S2: 8.67 | T2: https://www.etsy.com/listing/4556227760/dome-band-ring-wide-dome-ring-chunky
A3: 2 | B3: 4543752254 | C3: 1mm Thin Stacking Ring | Minimalist Dainty Band | Simple Everyday Gold Silver Jewelry | D3: Pasif | E3: band | F3: 1 | H3: 1.5 | I3: 1 | K3: tekil/aksan tas | Q3: =IF($L3="","",$L3*Varsayimlar!$B$5*(1+Varsayimlar!$B$7)) | R3: =IF($L3="","",$Q3+N($M3)+N($N3)+N($O3)) | S3: 1.2 | T3: https://www.etsy.com/listing/4543752254/1mm-thin-stacking-ring-minimalist-dainty
A4: 3 | B4: 4546852268 | C4: 2mm Smooth Gold Band Ring | Minimalist Wedding, Stacking, Promise Jewelry | D4: Pasif | E4: band | F4: 2 | H4: 1.5 | I4: 2 | K4: tam eternity | Q4: =IF($L4="","",$L4*Varsayimlar!$B$5*(1+Varsayimlar!$B$7)) | R4: =IF($L4="","",$Q4+N($M4)+N($N4)+N($O4)) | S4: 2.39 | T4: https://www.etsy.com/listing/4546852268/2mm-smooth-gold-band-ring-minimalist
A5: 4 | B5: 4549686009 | C5: 4mm Curved Wedding Band Ring | Minimalist Stacking Bridal Ring | D5: Pasif | E5: band | F5: 4 | H5: 1.5 | I5: 4 | K5: yok / none | Q5: =IF($L5="","",$L5*Varsayimlar!$B$5*(1+Varsayimlar!$B$7)) | R5: =IF($L5="","",$Q5+N($M5)+N($N5)+N($O5)) | S5: 4.79 | T5: https://www.etsy.com/listing/4549686009/4mm-curved-wedding-band-ring-minimalist
A6: 5 | B6: 4543147022 | C6: 4mm Smooth Band Ring | Minimalist Wedding Stacking Ring | D6: Pasif | E6: band | F6: 4 | H6: 1.5 | I6: 4 | K6: yok / none | Q6: =IF($L6="","",$L6*Varsayimlar!$B$5*(1+Varsayimlar!$B$7)) | R6: =IF($L6="","",$Q6+N($M6)+N($N6)+N($O6)) | S6: 4.79 | T6: https://www.etsy.com/listing/4543147022/4mm-smooth-band-ring-minimalist-wedding
A7: 6 | B7: 4547299090 | C7: 4mm Summit Band Ring | Minimalist Wedding, Stacking, Promise Band | Modern Comfort Fit | D7: Pasif | E7: band | F7: 4 | G7: 4 | H7: 1.5 | I7: 4 | K7: yok / none | Q7: =IF($L7="","",$L7*Varsayimlar!$B$5*(1+Varsayimlar!$B$7)) | R7: =IF($L7="","",$Q7+N($M7)+N($N7)+N($O7)) | S7: 4.79 | T7: https://www.etsy.com/listing/4547299090/4mm-summit-band-ring-minimalist-wedding
A8: 7 | B8: 4543746594 | C8: 6mm Curved Band Ring | Minimalist Gold Silver Modern Stacking Jewelry | D8: Pasif | E8: band | F8: 6 | H8: 1.5 | I8: 6 | K8: yok / none | Q8: =IF($L8="","",$L8*Varsayimlar!$B$5*(1+Varsayimlar!$B$7)) | R8: =IF($L8="","",$Q8+N($M8)+N($N8)+N($O8)) | S8: 7.18 | T8: https://www.etsy.com/listing/4543746594/6mm-curved-band-ring-minimalist-gold
A9: 8 | B9: 4543233648 | C9: 6mm Smooth Wedding Band | Minimalist Comfort Fit Ring, Stackable Gift | D9: Pasif | E9: band | F9: 6 | H9: 1.5 | I9: 6 | K9: yok / none | Q9: =IF($L9="","",$L9*Varsayimlar!$B$5*(1+Varsayimlar!$B$7)) | R9: =IF($L9="","",$Q9+N($M9)+N($N9)+N($O9)) | S9: 7.18 | T9: https://www.etsy.com/listing/4543233648/6mm-smooth-wedding-band-minimalist
A10: 9 | B10: 4558001828 | C10: 7mm Pave Diamond Star Open Ring | Celestial Minimalist Jewelry | D10: Pasif | E10: band | F10: 7 | H10: 1.5 | I10: 7 | K10: pave | Q10: =IF($L10="","",$L10*Varsayimlar!$B$5*(1+Varsayimlar!$B$7)) | R10: =IF($L10="","",$Q10+N($M10)+N($N10)+N($O10)) | S10: 8.37 | T10: https://www.etsy.com/listing/4558001828/7mm-pave-diamond-star-open-ring-o
A11: 10 | B11: 4552138588 | C11: Aurora Lab Grown Sapphire Eternity Ring | Blue Sapphire Band, 3.10mm Width | D11: Pasif | E11: band | F11: 3.1 | H11: 1.5 | I11: 3.1 | K11: tam eternity | Q11: =IF($L11="","",$L11*Varsayimlar!$B$5*(1+Varsayimlar!$B$7)) | R11: =IF($L11="","",$Q11+N($M11)+N($N11)+N($O11)) | S11: 3.71 | T11: https://www.etsy.com/listing/4552138588/aurora-lab-grown-sapphire-eternity-ring
A12: 11 | B12: 4554955252 | C12: Aurora Oval Eternity Ring | Minimalist Diamond Band, Stackable Wedding Ring | D12: Pasif | E12: band | F12: 2.5 | G12: 2.5 | H12: 1.5 | K12: tam eternity | Q12: =IF($L12="","",$L12*Varsayimlar!$B$5*(1+Varsayimlar!$B$7)) | R12: =IF($L12="","",$Q12+N($M12)+N($N12)+N($O12)) | S12: 2.99 | T12: https://www.etsy.com/listing/4554955252/oval-eternity-ring-aurora-diamond-ring
A13: 12 | B13: 4558666025 | C13: Baguette Diamond Eternity Ring | Thin Stackable Wedding Band | Minimalist Bridal Jewelry | D13: Pasif | E13: band | F13: 1.95 | H13: 1.5 | K13: tam eternity (baget) | Q13: =IF($L13="","",$L13*Varsayimlar!$B$5*(1+Varsayimlar!$B$7)) | R13: =IF($L13="","",$Q13+N($M13)+N($N13)+N($O13)) | S13: 2.33 | T13: https://www.etsy.com/listing/4558666025/baguette-eternity-ring-diamond-wedding
A14: 13 | B14: 4559889337 | C14: Baguette Diamond Half Eternity Ring | 1.45mm Slim Stacking Wedding Band | D14: Pasif | E14: band | F14: 1.45 | H14: 1.5 | I14: 1.45 | K14: yarim eternity (baget) | Q14: =IF($L14="","",$L14*Varsayimlar!$B$5*(1+Varsayimlar!$B$7)) | R14: =IF($L14="","",$Q14+N($M14)+N($N14)+N($O14)) | S14: 1.73 | T14: https://www.etsy.com/listing/4559889337/baguette-diamond-half-eternity-ring
A15: 14 | B15: 4559901602 | C15: Baguette Emerald Half Eternity Ring | Minimalist Stackable Band (2.35mm Top) | D15: Pasif | E15: band | F15: 2.35 | G15: 1.15 | H15: 1.5 | I15: 2.35 | K15: yarim eternity (baget) | Q15: =IF($L15="","",$L15*Varsayimlar!$B$5*(1+Varsayimlar!$B$7)) | R15: =IF($L15="","",$Q15+N($M15)+N($N15)+N($O15)) | S15: 2.09 | T15: https://www.etsy.com/listing/4559901602/emerald-baguette-half-eternity-ring
A16: 15 | B16: 4559862879 | C16: Baguette Emerald Open Ring | Minimalist Gold Gemstone Stackable Band | D16: Pasif | E16: band | F16: 1.1 | G16: 1.1 | H16: 1.5 | K16: baget | Q16: =IF($L16="","",$L16*Varsayimlar!$B$5*(1+Varsayimlar!$B$7)) | R16: =IF($L16="","",$Q16+N($M16)+N($N16)+N($O16)) | S16: 1.32 | T16: https://www.etsy.com/listing/4559862879/baguette-emerald-open-ring-emerald-green
A17: 16 | B17: 4553815586 | C17: Baguette Ring | Minimalist Stackable Diamond Band | Everyday Wedding Ring | D17: Pasif | E17: band | F17: 1 | G17: 1 | H17: 1.5 | I17: 1 | K17: baget | Q17: =IF($L17="","",$L17*Varsayimlar!$B$5*(1+Varsayimlar!$B$7)) | R17: =IF($L17="","",$Q17+N($M17)+N($N17)+N($O17)) | S17: 1.2 | T17: https://www.etsy.com/listing/4553815586/baguette-ring-minimalist-stackable
A18: 17 | B18: 4556230955 | C18: Bezel Emerald Half Eternity Band | Minimalist Stacking Ring | Anniversary Gift | D18: Pasif | E18: band | F18: 2.5 | G18: 1.3 | H18: 1.5 | K18: yarim eternity | Q18: =IF($L18="","",$L18*Varsayimlar!$B$5*(1+Varsayimlar!$B$7)) | R18: =IF($L18="","",$Q18+N($M18)+N($N18)+N($O18)) | S18: 2.27 | T18: https://www.etsy.com/listing/4556230955/bezel-emerald-half-eternity-band-emerald
A19: 18 | B19: 4556240933 | C19: Boa Gemstone Coil Ring | Serpent Inspired Wrap Statement Ring | D19: Pasif | E19: band | F19: 9.7 | H19: 1.5 | K19: tekil/aksan tas | Q19: =IF($L19="","",$L19*Varsayimlar!$B$5*(1+Varsayimlar!$B$7)) | R19: =IF($L19="","",$Q19+N($M19)+N($N19)+N($O19)) | S19: 11.6 | T19: https://www.etsy.com/listing/4556240933/boa-gemstone-coil-ring-serpent-inspired
A20: 19 | B20: 4549692483 | C20: Bold Diamond Eternity Band | 4mm Wedding Ring, Minimalist Bridal Stacking Band | D20: Pasif | E20: band | F20: 4 | H20: 1.5 | I20: 4 | K20: tam eternity | Q20: =IF($L20="","",$L20*Varsayimlar!$B$5*(1+Varsayimlar!$B$7)) | R20: =IF($L20="","",$Q20+N($M20)+N($N20)+N($O20)) | S20: 4.79 | T20: https://www.etsy.com/listing/4549692483/bold-diamond-eternity-band-4mm-wedding
A21: 20 | B21: 4544917788 | C21: Bold Diamond Eternity Ring | 2.6mm Gold Wedding Band, Stacking Ring | D21: Pasif | E21: band | F21: 2.6 | H21: 1.5 | I21: 2.6 | K21: tam eternity | Q21: =IF($L21="","",$L21*Varsayimlar!$B$5*(1+Varsayimlar!$B$7)) | R21: =IF($L21="","",$Q21+N($M21)+N($N21)+N($O21)) | S21: 3.11 | T21: https://www.etsy.com/listing/4544917788/bold-diamond-eternity-ring-26mm-gold
A22: 21 | B22: 4552128868 | C22: Bold Dot Ring | Minimalist Stacking Band | Modern Everyday Jewelry (3.6mm Wide) | D22: Pasif | E22: band | F22: 3.6 | H22: 1.6 | I22: 3.6 | K22: yok / none | Q22: =IF($L22="","",$L22*Varsayimlar!$B$5*(1+Varsayimlar!$B$7)) | R22: =IF($L22="","",$Q22+N($M22)+N($N22)+N($O22)) | S22: 4.59 | T22: https://www.etsy.com/listing/4552128868/bold-dot-ring-minimalist-stacking-band
A23: 22 | B23: 4545510477 | C23: Bold Line Eternity Band Ring | 3mm Minimalist Stacking Wedding Anniversary Band | D23: Pasif | E23: band | F23: 3 | H23: 1.5 | I23: 3 | K23: tam eternity | Q23: =IF($L23="","",$L23*Varsayimlar!$B$5*(1+Varsayimlar!$B$7)) | R23: =IF($L23="","",$Q23+N($M23)+N($N23)+N($O23)) | S23: 3.59 | T23: https://www.etsy.com/listing/4545510477/bold-line-eternity-band-ring-3mm
A24: 23 | B24: 4550930017 | C24: Bold Puzzle Stacking Ring | 3mm Gold Band, Modern Minimalist Statement Jewelry | D24: Pasif | E24: band | F24: 3 | G24: 3 | H24: 1.5 | I24: 3 | K24: yok / none | Q24: =IF($L24="","",$L24*Varsayimlar!$B$5*(1+Varsayimlar!$B$7)) | R24: =IF($L24="","",$Q24+N($M24)+N($N24)+N($O24)) | S24: 3.59 | T24: https://www.etsy.com/listing/4550930017/bold-puzzle-stacking-ring-3mm-gold-band
A25: 24 | B25: 4551550234 | C25: Bold Round Signet Ring | 13mm Top Width, 4mm Shank | Modern Statement Jewelry | D25: Pasif | E25: signet | F25: 13 | G25: 4 | H25: 1.5 | I25: 13 | K25: yok / none | Q25: =IF($L25="","",$L25*Varsayimlar!$B$5*(1+Varsayimlar!$B$7)) | R25: =IF($L25="","",$Q25+N($M25)+N($N25)+N($O25)) | S25: 10.17 | T25: https://www.etsy.com/listing/4551550234/bold-round-signet-ring-13mm-top-width
A26: 25 | B26: 4554965833 | C26: Bold Stacker Ring | Minimalist Band, 3mm Width, Everyday Jewelry | D26: Pasif | E26: band | F26: 3 | H26: 1.5 | I26: 3 | K26: yok / none | Q26: =IF($L26="","",$L26*Varsayimlar!$B$5*(1+Varsayimlar!$B$7)) | R26: =IF($L26="","",$Q26+N($M26)+N($N26)+N($O26)) | S26: 3.59 | T26: https://www.etsy.com/listing/4554965833/bold-stacking-ring-chunky-stacker-ring
A27: 26 | B27: 4546827813 | C27: Braided Wedding Band | Minimalist Woven Ring, Stackable Jewelry (4.45mm) | D27: Pasif | E27: band | F27: 4.45 | H27: 1.5 | I27: 4.45 | K27: tam eternity | Q27: =IF($L27="","",$L27*Varsayimlar!$B$5*(1+Varsayimlar!$B$7)) | R27: =IF($L27="","",$Q27+N($M27)+N($N27)+N($O27)) | S27: 5.32 | T27: https://www.etsy.com/listing/4546827813/braided-wedding-band-minimalist-woven
A28: 27 | B28: 4554957582 | C28: Celestial Dome Ring | Sterling Silver Minimalist Band | Everyday Stackable Jewelry | D28: Pasif | E28: dome | F28: 5.6 | G28: 1.65 | H28: 1.5 | K28: yok / none | Q28: =IF($L28="","",$L28*Varsayimlar!$B$5*(1+Varsayimlar!$B$7)) | R28: =IF($L28="","",$Q28+N($M28)+N($N28)+N($O28)) | S28: 4.34 | T28: https://www.etsy.com/listing/4554957582/celestial-dome-ring-sterling-silver-dome
A29: 28 | B29: 4549031600 | C29: Charlotte Bold Gold Ring | Wide Band Minimalist Statement Jewelry | D29: Pasif | E29: band | F29: 9.35 | H29: 1.5 | K29: yok / none | Q29: =IF($L29="","",$L29*Varsayimlar!$B$5*(1+Varsayimlar!$B$7)) | R29: =IF($L29="","",$Q29+N($M29)+N($N29)+N($O29)) | S29: 11.19 | T29: https://www.etsy.com/listing/4549031600/charlotte-bold-gold-ring-wide-band
A30: 29 | B30: 4552100498 | C30: Charlotte Crest Gold Stacking Ring | Minimalist Dainty Band, 2.8mm Everyday Jewelry | D30: Pasif | E30: band | F30: 2.8 | H30: 1.5 | I30: 2.8 | K30: yok / none | Q30: =IF($L30="","",$L30*Varsayimlar!$B$5*(1+Varsayimlar!$B$7)) | R30: =IF($L30="","",$Q30+N($M30)+N($N30)+N($O30)) | S30: 3.35 | T30: https://www.etsy.com/listing/4552100498/charlotte-crest-gold-stacking-ring
A31: 30 | B31: 4554964031 | C31: Charlotte Ring | 6.35mm Wide Chunky Band Statement Ring | D31: Pasif | E31: band | F31: 6.35 | H31: 1.5 | I31: 6.35 | K31: yok / none | Q31: =IF($L31="","",$L31*Varsayimlar!$B$5*(1+Varsayimlar!$B$7)) | R31: =IF($L31="","",$Q31+N($M31)+N($N31)+N($O31)) | S31: 7.6 | T31: https://www.etsy.com/listing/4554964031/charlotte-ring-chunky-band-ring
A32: 31 | B32: 4550953712 | C32: Charlotte Stacker Ring Set | Minimalist Band, 6.20mm Width, Dainty Jewelry | D32: Pasif | E32: band | F32: 6.2 | H32: 1.5 | I32: 6.2 | K32: yok / none | Q32: =IF($L32="","",$L32*Varsayimlar!$B$5*(1+Varsayimlar!$B$7)) | R32: =IF($L32="","",$Q32+N($M32)+N($N32)+N($O32)) | S32: 7.42 | T32: https://www.etsy.com/listing/4550953712/charlotte-stacker-ring-set-minimalist
A33: 32 | B33: 4553157256 | C33: Chunky Dome Ring | Modern Gold Statement Band | Minimalist Jewelry (6.3mm Top Width) | D33: Pasif | E33: dome | F33: 6.3 | G33: 2 | H33: 1.5 | I33: 6.3 | K33: yok / none | Q33: =IF($L33="","",$L33*Varsayimlar!$B$5*(1+Varsayimlar!$B$7)) | R33: =IF($L33="","",$Q33+N($M33)+N($N33)+N($O33)) | S33: 4.96 | T33: https://www.etsy.com/listing/4553157256/chunky-dome-ring-modern-gold-statement
A34: 33 | B34: 4556249030 | C34: Chunky Dome Statement Ring | Minimalist Gold Band, Stackable Modern Jewelry | D34: Pasif | E34: dome | F34: 5.8 | H34: 1.5 | K34: yok / none | Q34: =IF($L34="","",$L34*Varsayimlar!$B$5*(1+Varsayimlar!$B$7)) | R34: =IF($L34="","",$Q34+N($M34)+N($N34)+N($O34)) | S34: 6.94 | T34: https://www.etsy.com/listing/4556249030/dome-figure-ring-o-dome-statement-ring-o
A35: 34 | B35: 4552026081 | C35: Colosseum Wide Band Ring | Modern Minimalist Gold Statement Jewelry | D35: Pasif | E35: band | F35: 1.5 | H35: 1.5 | K35: yok / none | Q35: =IF($L35="","",$L35*Varsayimlar!$B$5*(1+Varsayimlar!$B$7)) | R35: =IF($L35="","",$Q35+N($M35)+N($N35)+N($O35)) | S35: 1.79 | T35: https://www.etsy.com/listing/4552026081/colosseum-wide-band-ring-modern
A36: 35 | B36: 4552085145 | C36: Courage Signet Ring | Bold Minimalist Statement Jewelry (13mm Top) | D36: Pasif | E36: signet | F36: 13 | G36: 1.7 | H36: 1.5 | I36: 13 | K36: yok / none | Q36: =IF($L36="","",$L36*Varsayimlar!$B$5*(1+Varsayimlar!$B$7)) | R36: =IF($L36="","",$Q36+N($M36)+N($N36)+N($O36)) | S36: 8.79 | T36: https://www.etsy.com/listing/4552085145/courage-signet-ring-bold-minimalist
A37: 36 | B37: 4551576045 | C37: Curved Gold Band Ring | Minimalist 2mm Stacking Wedding Ring | D37: Pasif | E37: band | F37: 2 | H37: 1.5 | I37: 2 | K37: yok / none | Q37: =IF($L37="","",$L37*Varsayimlar!$B$5*(1+Varsayimlar!$B$7)) | R37: =IF($L37="","",$Q37+N($M37)+N($N37)+N($O37)) | S37: 2.39 | T37: https://www.etsy.com/listing/4551576045/curved-gold-band-ring-minimalist-2mm
A38: 37 | B38: 4538876982 | C38: Curved Pave Diamond Nesting Ring, Solid Gold | D38: Pasif | E38: band | F38: 1.5 | H38: 1.5 | K38: pave | Q38: =IF($L38="","",$L38*Varsayimlar!$B$5*(1+Varsayimlar!$B$7)) | R38: =IF($L38="","",$Q38+N($M38)+N($N38)+N($O38)) | S38: 1.79 | T38: https://www.etsy.com/listing/4538876982/dome-pave-diamond-ring-curved-wave
A39: 38 | B39: 4557310374 | C39: Dainty Pearl and Diamond Ring | Slim 1mm Band, Minimalist Jewelry | D39: Pasif | E39: band | F39: 1 | H39: 1.5 | I39: 1 | K39: yok / none | Q39: =IF($L39="","",$L39*Varsayimlar!$B$5*(1+Varsayimlar!$B$7)) | R39: =IF($L39="","",$Q39+N($M39)+N($N39)+N($O39)) | S39: 1.2 | T39: https://www.etsy.com/listing/4557310374/beverly-ring-dainty-stacking-ring-slim
A40: 39 | B40: 4545535248 | C40: Diamond Cluster Engagement Ring | Elegant Statement Bridal Wedding Band | D40: Pasif | E40: band | F40: 7 | G40: 2 | H40: 1.5 | K40: tekil/aksan tas | Q40: =IF($L40="","",$L40*Varsayimlar!$B$5*(1+Varsayimlar!$B$7)) | R40: =IF($L40="","",$Q40+N($M40)+N($N40)+N($O40)) | S40: 5.38 | T40: https://www.etsy.com/listing/4545535248/diamond-cluster-engagement-ring-elegant
...

Sheet Varsayimlar
A1: Varsayimlar / Assumptions
A3: Girdi | B3: Deger | C3: Kaynak / not
A4: 10K altin alis (USD/gram) | B4: 65 | C4: Panel > Ayarlar > Altin (gold_settings.purchase_price_10k_cents=6500)
A5: 14K altin alis (USD/gram) | B5: 101 | C5: Panel > Ayarlar > Altin (gold_settings.purchase_price_14k_cents=10100)
A6: 18K altin alis (USD/gram) | B6: 130 | C6: VARSAYIM - panelde 18K kaydi YOK. 14K'nin saflik oraniyla turetildi: 101/0.583*0.750.
A7: Fire / kayip orani | B7: 0.07 | C7: EON v4 motoru (lib/pricing/gold-index.ts, V4.fire). Uretici kendi firesini veriyorsa onu kullanin.
A8: Referans beden | B8: US 7 | C8: Gram talebi bu bedende. Panel diger bedenlere olcekler.
A9: Referans kalinlik (mm) | B9: 1.5 | C9: 93 listingin 63'unde aciklamada yazili; gozlenen araligin tamami 1.50-1.60 mm.
A11: Metal maliyeti = gram x 14K alis x (1 + fire). Toplam maliyet = metal + iscilik + tas/mihlama + dokum/diger.
A12: SATIS fiyati bu sayfada YOK - once gercek maliyet toplanir, fiyat sonra panelde kurulur.

Sheet Nasil Doldurulur
A1: Nasil doldurulur / How to fill
A3: Amac | B3: 93 listing icin GERCEK maliyet girdilerini ureticiden almak. Panelde su an gram YOK; tum listingler tek tip 366 USD fiyatta.
A4: Doldurulacak alanlar | B4: Yalnizca SARI hucreler: GRAM 14K (US 7), ISCILIK USD, TAS+MIHLAMA USD, DOKUM+DIGER USD, URETICI NOTU.
A5: Gram | B5: 14 ayar ve US 7 beden icin parca basi net gram. Tek referans yeter; diger karat/bedenler panelde hesaplanir.
A6: Iscilik | B6: Parca basi iscilik (USD). Tas mihlama HARIC - o ayri sutunda.
A7: Tas + mihlama | B7: Tas bedeli + mihlama iscilligi toplami (USD). Tas yoksa 0 yazin.
A8: Dokum + diger | B8: Dokum, cila, kaplama vb. varsa (USD). Yoksa 0.
A9: KONTROL sutunu | B9: Bos. Onceki surumde 9 satir isaretliydi; 2026-09-08 denetiminde hepsi YANLIS ALARM cikti - 8 satirda kalinlik genislik sutununa yazilmisti (duzeltildi), 1 satirda basliktaki mm tas olcusuydu.
A10: Hesaplanan sutunlar | B10: 'Metal maliyeti' ve 'TOPLAM MALIYET' otomatik hesaplanir - elle doldurmayin.
A11: Bizim gram tahminimiz | B11: Sadece BUYUKLUK FIKRI icin. Olcuden hesaplanan kaba tahmindir, dogrulanmis degildir - referans almayin.
A13: ORNEK SATIR (beklenen format)
A14: Urun | B14: GRAM 14K (US 7) | C14: ISCILIK USD | D14: TAS+MIHLAMA USD | E14: DOKUM+DIGER USD | F14: URETICI NOTU
A15: 2mm Smooth Gold Band Ring | B15: 2.05 | C15: 100 | D15: 0 | E15: 12 | F15: Duz band, tassiz. US7 net gram.
