Workbook

Sheet Ayarlar
A1: JADE GOLD NYC — FİYAT AYARLARI
A2: AYAR | B2: DEĞER | C2: AÇIKLAMA
A3: Altın maliyeti ($/gram) | B3: 106 | C3: Her şey dahil tedarikçi faturası: ham altın + işçilik + taş
A4: Kargo ($) | B4: 5 | C4: Ücretsiz kargo — bedeli satıcıda
A5: Ambalaj ($) | B5: 1.5
A6: Etsy indirimi | B6: 0.15 | C6: Kalıcı mağaza indirimi — tahsilat = liste × 0,85
A7: Etsy oransal kesinti | B7: 0.095 | C7: %6,5 işlem + %3 ödeme
A8: Etsy sabit kesinti ($) | B8: 0.25
A9: Hedef net marj | B9: 0.2 | C9: Fiyat önerisi bu marja göre hesaplanır
A11: Sarı hücreler düzenlenebilir. Değiştirince tüm sekmeler yeniden hesaplanır.

Sheet Eksik Gramlar
A1: Bölüm | B1: Listing | C1: Etsy ID | D1: SKU | E1: Fiyat $ | F1: GRAM | G1: Maliyet $ | H1: Breakeven $ | I1: Hedef Fiyat $ | J1: Marj | K1: Durum | L1: Etsy Linki
A2: chains | B2: 10K Gold Rope Chain Necklace – Twisted Diamond Cut | C2: 1862428966 | D2: C1862428966 | E2: 226.39 | G2: =IF(F2="","",F2*Ayarlar!$B$3+Ayarlar!$B$4+Ayarlar!$B$5) | H2: =IF(F2="","",ROUNDUP(((F2*Ayarlar!$B$3+Ayarlar!$B$4+Ayarlar!$B$5)+Ayarlar!$B$8)/((1-Ayarlar!$B$6)*(1-Ayarlar!$B$7)),0)) | I2: =IF(F2="","",ROUNDUP(((F2*Ayarlar!$B$3+Ayarlar!$B$4+Ayarlar!$B$5)+Ayarlar!$B$8)/((1-Ayarlar!$B$6)*(1-Ayarlar!$B$7-Ayarlar!$B$9)),0)) | J2: =IF(OR(F2="",E2=""),"",(E2*(1-Ayarlar!$B$6)-(E2*(1-Ayarlar!$B$6)*Ayarlar!$B$7+Ayarlar!$B$8)-(F2*Ayarlar!$B$3+Ayarlar!$B$4+Ayarlar!$B$5))/(E2*(1-Ayarlar!$B$6))) | K2: =IF(F2="","GRAM EKSİK",IF(E2>30000,"FİYAT ŞÜPHELİ",IF(J2<0,"ZARARDA",IF(E2<H2,"RİSKLİ","ok")))) | L2: https://www.etsy.com/listing/1862428966
A3: chains | B3: 10K Solid Gold Herringbone Necklace, High Polish Snake Chain | C3: 1294201622 | D3: R1294201622 | E3: 86.27 | G3: =IF(F3="","",F3*Ayarlar!$B$3+Ayarlar!$B$4+Ayarlar!$B$5) | H3: =IF(F3="","",ROUNDUP(((F3*Ayarlar!$B$3+Ayarlar!$B$4+Ayarlar!$B$5)+Ayarlar!$B$8)/((1-Ayarlar!$B$6)*(1-Ayarlar!$B$7)),0)) | I3: =IF(F3="","",ROUNDUP(((F3*Ayarlar!$B$3+Ayarlar!$B$4+Ayarlar!$B$5)+Ayarlar!$B$8)/((1-Ayarlar!$B$6)*(1-Ayarlar!$B$7-Ayarlar!$B$9)),0)) | J3: =IF(OR(F3="",E3=""),"",(E3*(1-Ayarlar!$B$6)-(E3*(1-Ayarlar!$B$6)*Ayarlar!$B$7+Ayarlar!$B$8)-(F3*Ayarlar!$B$3+Ayarlar!$B$4+Ayarlar!$B$5))/(E3*(1-Ayarlar!$B$6))) | K3: =IF(F3="","GRAM EKSİK",IF(E3>30000,"FİYAT ŞÜPHELİ",IF(J3<0,"ZARARDA",IF(E3<H3,"RİSKLİ","ok")))) | L3: https://www.etsy.com/listing/1294201622
A4: chains | B4: 14K Gold Necklace, Solid White Bead Ball Chain Design | C4: 4546907749 | D4: CWM42F-16 | E4: 812.7 | G4: =IF(F4="","",F4*Ayarlar!$B$3+Ayarlar!$B$4+Ayarlar!$B$5) | H4: =IF(F4="","",ROUNDUP(((F4*Ayarlar!$B$3+Ayarlar!$B$4+Ayarlar!$B$5)+Ayarlar!$B$8)/((1-Ayarlar!$B$6)*(1-Ayarlar!$B$7)),0)) | I4: =IF(F4="","",ROUNDUP(((F4*Ayarlar!$B$3+Ayarlar!$B$4+Ayarlar!$B$5)+Ayarlar!$B$8)/((1-Ayarlar!$B$6)*(1-Ayarlar!$B$7-Ayarlar!$B$9)),0)) | J4: =IF(OR(F4="",E4=""),"",(E4*(1-Ayarlar!$B$6)-(E4*(1-Ayarlar!$B$6)*Ayarlar!$B$7+Ayarlar!$B$8)-(F4*Ayarlar!$B$3+Ayarlar!$B$4+Ayarlar!$B$5))/(E4*(1-Ayarlar!$B$6))) | K4: =IF(F4="","GRAM EKSİK",IF(E4>30000,"FİYAT ŞÜPHELİ",IF(J4<0,"ZARARDA",IF(E4<H4,"RİSKLİ","ok")))) | L4: https://www.etsy.com/listing/4546907749
A5: chains | B5: 14K Gold Necklace, Solid White Bead Ball Chain Design | C5: 4546907749 | D5: CWM42F-18 | E5: 914.28 | G5: =IF(F5="","",F5*Ayarlar!$B$3+Ayarlar!$B$4+Ayarlar!$B$5) | H5: =IF(F5="","",ROUNDUP(((F5*Ayarlar!$B$3+Ayarlar!$B$4+Ayarlar!$B$5)+Ayarlar!$B$8)/((1-Ayarlar!$B$6)*(1-Ayarlar!$B$7)),0)) | I5: =IF(F5="","",ROUNDUP(((F5*Ayarlar!$B$3+Ayarlar!$B$4+Ayarlar!$B$5)+Ayarlar!$B$8)/((1-Ayarlar!$B$6)*(1-Ayarlar!$B$7-Ayarlar!$B$9)),0)) | J5: =IF(OR(F5="",E5=""),"",(E5*(1-Ayarlar!$B$6)-(E5*(1-Ayarlar!$B$6)*Ayarlar!$B$7+Ayarlar!$B$8)-(F5*Ayarlar!$B$3+Ayarlar!$B$4+Ayarlar!$B$5))/(E5*(1-Ayarlar!$B$6))) | K5: =IF(F5="","GRAM EKSİK",IF(E5>30000,"FİYAT ŞÜPHELİ",IF(J5<0,"ZARARDA",IF(E5<H5,"RİSKLİ","ok")))) | L5: https://www.etsy.com/listing/4546907749
A6: chains | B6: 14K Gold Necklace, Solid White Bead Ball Chain Design | C6: 4546907749 | D6: CWM42F-20 | E6: 1015.87 | G6: =IF(F6="","",F6*Ayarlar!$B$3+Ayarlar!$B$4+Ayarlar!$B$5) | H6: =IF(F6="","",ROUNDUP(((F6*Ayarlar!$B$3+Ayarlar!$B$4+Ayarlar!$B$5)+Ayarlar!$B$8)/((1-Ayarlar!$B$6)*(1-Ayarlar!$B$7)),0)) | I6: =IF(F6="","",ROUNDUP(((F6*Ayarlar!$B$3+Ayarlar!$B$4+Ayarlar!$B$5)+Ayarlar!$B$8)/((1-Ayarlar!$B$6)*(1-Ayarlar!$B$7-Ayarlar!$B$9)),0)) | J6: =IF(OR(F6="",E6=""),"",(E6*(1-Ayarlar!$B$6)-(E6*(1-Ayarlar!$B$6)*Ayarlar!$B$7+Ayarlar!$B$8)-(F6*Ayarlar!$B$3+Ayarlar!$B$4+Ayarlar!$B$5))/(E6*(1-Ayarlar!$B$6))) | K6: =IF(F6="","GRAM EKSİK",IF(E6>30000,"FİYAT ŞÜPHELİ",IF(J6<0,"ZARARDA",IF(E6<H6,"RİSKLİ","ok")))) | L6: https://www.etsy.com/listing/4546907749
A7: chains | B7: 14K Gold Necklace, Solid White Bead Ball Chain Design | C7: 4546907749 | D7: CWM42F-22 | E7: 1117.46 | G7: =IF(F7="","",F7*Ayarlar!$B$3+Ayarlar!$B$4+Ayarlar!$B$5) | H7: =IF(F7="","",ROUNDUP(((F7*Ayarlar!$B$3+Ayarlar!$B$4+Ayarlar!$B$5)+Ayarlar!$B$8)/((1-Ayarlar!$B$6)*(1-Ayarlar!$B$7)),0)) | I7: =IF(F7="","",ROUNDUP(((F7*Ayarlar!$B$3+Ayarlar!$B$4+Ayarlar!$B$5)+Ayarlar!$B$8)/((1-Ayarlar!$B$6)*(1-Ayarlar!$B$7-Ayarlar!$B$9)),0)) | J7: =IF(OR(F7="",E7=""),"",(E7*(1-Ayarlar!$B$6)-(E7*(1-Ayarlar!$B$6)*Ayarlar!$B$7+Ayarlar!$B$8)-(F7*Ayarlar!$B$3+Ayarlar!$B$4+Ayarlar!$B$5))/(E7*(1-Ayarlar!$B$6))) | K7: =IF(F7="","GRAM EKSİK",IF(E7>30000,"FİYAT ŞÜPHELİ",IF(J7<0,"ZARARDA",IF(E7<H7,"RİSKLİ","ok")))) | L7: https://www.etsy.com/listing/4546907749
A8: chains | B8: 14K Gold Necklace, Solid White Bead Ball Chain Design | C8: 4546907749 | D8: CWM42F-24 | E8: 1219.05 | G8: =IF(F8="","",F8*Ayarlar!$B$3+Ayarlar!$B$4+Ayarlar!$B$5) | H8: =IF(F8="","",ROUNDUP(((F8*Ayarlar!$B$3+Ayarlar!$B$4+Ayarlar!$B$5)+Ayarlar!$B$8)/((1-Ayarlar!$B$6)*(1-Ayarlar!$B$7)),0)) | I8: =IF(F8="","",ROUNDUP(((F8*Ayarlar!$B$3+Ayarlar!$B$4+Ayarlar!$B$5)+Ayarlar!$B$8)/((1-Ayarlar!$B$6)*(1-Ayarlar!$B$7-Ayarlar!$B$9)),0)) | J8: =IF(OR(F8="",E8=""),"",(E8*(1-Ayarlar!$B$6)-(E8*(1-Ayarlar!$B$6)*Ayarlar!$B$7+Ayarlar!$B$8)-(F8*Ayarlar!$B$3+Ayarlar!$B$4+Ayarlar!$B$5))/(E8*(1-Ayarlar!$B$6))) | K8: =IF(F8="","GRAM EKSİK",IF(E8>30000,"FİYAT ŞÜPHELİ",IF(J8<0,"ZARARDA",IF(E8<H8,"RİSKLİ","ok")))) | L8: https://www.etsy.com/listing/4546907749
A9: chains | B9: 14K Gold Necklace, Solid White Bead Ball Chain Design | C9: 4546907749 | D9: CWM43F-16 | E9: 1741.5 | G9: =IF(F9="","",F9*Ayarlar!$B$3+Ayarlar!$B$4+Ayarlar!$B$5) | H9: =IF(F9="","",ROUNDUP(((F9*Ayarlar!$B$3+Ayarlar!$B$4+Ayarlar!$B$5)+Ayarlar!$B$8)/((1-Ayarlar!$B$6)*(1-Ayarlar!$B$7)),0)) | I9: =IF(F9="","",ROUNDUP(((F9*Ayarlar!$B$3+Ayarlar!$B$4+Ayarlar!$B$5)+Ayarlar!$B$8)/((1-Ayarlar!$B$6)*(1-Ayarlar!$B$7-Ayarlar!$B$9)),0)) | J9: =IF(OR(F9="",E9=""),"",(E9*(1-Ayarlar!$B$6)-(E9*(1-Ayarlar!$B$6)*Ayarlar!$B$7+Ayarlar!$B$8)-(F9*Ayarlar!$B$3+Ayarlar!$B$4+Ayarlar!$B$5))/(E9*(1-Ayarlar!$B$6))) | K9: =IF(F9="","GRAM EKSİK",IF(E9>30000,"FİYAT ŞÜPHELİ",IF(J9<0,"ZARARDA",IF(E9<H9,"RİSKLİ","ok")))) | L9: https://www.etsy.com/listing/4546907749
A10: chains | B10: 14K Gold Necklace, Solid White Bead Ball Chain Design | C10: 4546907749 | D10: CWM43F-18 | E10: 1950.48 | G10: =IF(F10="","",F10*Ayarlar!$B$3+Ayarlar!$B$4+Ayarlar!$B$5) | H10: =IF(F10="","",ROUNDUP(((F10*Ayarlar!$B$3+Ayarlar!$B$4+Ayarlar!$B$5)+Ayarlar!$B$8)/((1-Ayarlar!$B$6)*(1-Ayarlar!$B$7)),0)) | I10: =IF(F10="","",ROUNDUP(((F10*Ayarlar!$B$3+Ayarlar!$B$4+Ayarlar!$B$5)+Ayarlar!$B$8)/((1-Ayarlar!$B$6)*(1-Ayarlar!$B$7-Ayarlar!$B$9)),0)) | J10: =IF(OR(F10="",E10=""),"",(E10*(1-Ayarlar!$B$6)-(E10*(1-Ayarlar!$B$6)*Ayarlar!$B$7+Ayarlar!$B$8)-(F10*Ayarlar!$B$3+Ayarlar!$B$4+Ayarlar!$B$5))/(E10*(1-Ayarlar!$B$6))) | K10: =IF(F10="","GRAM EKSİK",IF(E10>30000,"FİYAT ŞÜPHELİ",IF(J10<0,"ZARARDA",IF(E10<H10,"RİSKLİ","ok")))) | L10: https://www.etsy.com/listing/4546907749
A11: chains | B11: 14K Gold Necklace, Solid White Bead Ball Chain Design | C11: 4546907749 | D11: CWM43F-20 | E11: 2147.85 | G11: =IF(F11="","",F11*Ayarlar!$B$3+Ayarlar!$B$4+Ayarlar!$B$5) | H11: =IF(F11="","",ROUNDUP(((F11*Ayarlar!$B$3+Ayarlar!$B$4+Ayarlar!$B$5)+Ayarlar!$B$8)/((1-Ayarlar!$B$6)*(1-Ayarlar!$B$7)),0)) | I11: =IF(F11="","",ROUNDUP(((F11*Ayarlar!$B$3+Ayarlar!$B$4+Ayarlar!$B$5)+Ayarlar!$B$8)/((1-Ayarlar!$B$6)*(1-Ayarlar!$B$7-Ayarlar!$B$9)),0)) | J11: =IF(OR(F11="",E11=""),"",(E11*(1-Ayarlar!$B$6)-(E11*(1-Ayarlar!$B$6)*Ayarlar!$B$7+Ayarlar!$B$8)-(F11*Ayarlar!$B$3+Ayarlar!$B$4+Ayarlar!$B$5))/(E11*(1-Ayarlar!$B$6))) | K11: =IF(F11="","GRAM EKSİK",IF(E11>30000,"FİYAT ŞÜPHELİ",IF(J11<0,"ZARARDA",IF(E11<H11,"RİSKLİ","ok")))) | L11: https://www.etsy.com/listing/4546907749
A12: chains | B12: 14K Gold Necklace, Solid White Bead Ball Chain Design | C12: 4546907749 | D12: CWM43F-22 | E12: 2322 | G12: =IF(F12="","",F12*Ayarlar!$B$3+Ayarlar!$B$4+Ayarlar!$B$5) | H12: =IF(F12="","",ROUNDUP(((F12*Ayarlar!$B$3+Ayarlar!$B$4+Ayarlar!$B$5)+Ayarlar!$B$8)/((1-Ayarlar!$B$6)*(1-Ayarlar!$B$7)),0)) | I12: =IF(F12="","",ROUNDUP(((F12*Ayarlar!$B$3+Ayarlar!$B$4+Ayarlar!$B$5)+Ayarlar!$B$8)/((1-Ayarlar!$B$6)*(1-Ayarlar!$B$7-Ayarlar!$B$9)),0)) | J12: =IF(OR(F12="",E12=""),"",(E12*(1-Ayarlar!$B$6)-(E12*(1-Ayarlar!$B$6)*Ayarlar!$B$7+Ayarlar!$B$8)-(F12*Ayarlar!$B$3+Ayarlar!$B$4+Ayarlar!$B$5))/(E12*(1-Ayarlar!$B$6))) | K12: =IF(F12="","GRAM EKSİK",IF(E12>30000,"FİYAT ŞÜPHELİ",IF(J12<0,"ZARARDA",IF(E12<H12,"RİSKLİ","ok")))) | L12: https://www.etsy.com/listing/4546907749
A13: chains | B13: 14K Gold Necklace, Solid White Bead Ball Chain Design | C13: 4546907749 | D13: CWM43F-24 | E13: 2554.2 | G13: =IF(F13="","",F13*Ayarlar!$B$3+Ayarlar!$B$4+Ayarlar!$B$5) | H13: =IF(F13="","",ROUNDUP(((F13*Ayarlar!$B$3+Ayarlar!$B$4+Ayarlar!$B$5)+Ayarlar!$B$8)/((1-Ayarlar!$B$6)*(1-Ayarlar!$B$7)),0)) | I13: =IF(F13="","",ROUNDUP(((F13*Ayarlar!$B$3+Ayarlar!$B$4+Ayarlar!$B$5)+Ayarlar!$B$8)/((1-Ayarlar!$B$6)*(1-Ayarlar!$B$7-Ayarlar!$B$9)),0)) | J13: =IF(OR(F13="",E13=""),"",(E13*(1-Ayarlar!$B$6)-(E13*(1-Ayarlar!$B$6)*Ayarlar!$B$7+Ayarlar!$B$8)-(F13*Ayarlar!$B$3+Ayarlar!$B$4+Ayarlar!$B$5))/(E13*(1-Ayarlar!$B$6))) | K13: =IF(F13="","GRAM EKSİK",IF(E13>30000,"FİYAT ŞÜPHELİ",IF(J13<0,"ZARARDA",IF(E13<H13,"RİSKLİ","ok")))) | L13: https://www.etsy.com/listing/4546907749
... A122: protection | B122: 14K Gold Teddy Bear CZ Pendant Necklace, Miami Cuban Chain | C122: 1595078873 | D122: PBEAR-3 | E122: 1111.76 | G122: =IF(F122="","",F122*Ayarlar!$B$3+Ayarlar!$B$4+Ayarlar!$B$5) | H122: =IF(F122="","",ROUNDUP(((F122*Ayarlar!$B$3+Ayarlar!$B$4+Ayarlar!$B$5)+Ayarlar!$B$8)/((1-Ayarlar!$B$6)*(1-Ayarlar!$B$7)),0)) | I122: =IF(F122="","",ROUNDUP(((F122*Ayarlar!$B$3+Ayarlar!$B$4+Ayarlar!$B$5)+Ayarlar!$B$8)/((1-Ayarlar!$B$6)*(1-Ayarlar!$B$7-Ayarlar!$B$9)),0)) | J122: =IF(OR(F122="",E122=""),"",(E122*(1-Ayarlar!$B$6)-(E122*(1-Ayarlar!$B$6)*Ayarlar!$B$7+Ayarlar!$B$8)-(F122*Ayarlar!$B$3+Ayarlar!$B$4+Ayarlar!$B$5))/(E122*(1-Ayarlar!$B$6))) | K122: =IF(F122="","GRAM EKSİK",IF(E122>30000,"FİYAT ŞÜPHELİ",IF(J122<0,"ZARARDA",IF(E122<H122,"RİSKLİ","ok")))) | L122: https://www.etsy.com/listing/1595078873

Sheet Tüm Varyantlar
A1: Bölüm | B1: Listing | C1: Etsy ID | D1: SKU | E1: Gram Kaynağı | F1: Fiyat $ | G1: GRAM | H1: Maliyet $ | I1: Breakeven $ | J1: Hedef Fiyat $ | K1: Marj | L1: Durum | M1: Etsy Linki
A2: chains | B2: 10K Gold Rope Chain Necklace – Twisted Diamond Cut | C2: 1862428966 | D2: C1862428966 | E2: — | F2: 226.39 | H2: =IF(G2="","",G2*Ayarlar!$B$3+Ayarlar!$B$4+Ayarlar!$B$5) | I2: =IF(G2="","",ROUNDUP(((G2*Ayarlar!$B$3+Ayarlar!$B$4+Ayarlar!$B$5)+Ayarlar!$B$8)/((1-Ayarlar!$B$6)*(1-Ayarlar!$B$7)),0)) | J2: =IF(G2="","",ROUNDUP(((G2*Ayarlar!$B$3+Ayarlar!$B$4+Ayarlar!$B$5)+Ayarlar!$B$8)/((1-Ayarlar!$B$6)*(1-Ayarlar!$B$7-Ayarlar!$B$9)),0)) | K2: =IF(OR(G2="",F2=""),"",(F2*(1-Ayarlar!$B$6)-(F2*(1-Ayarlar!$B$6)*Ayarlar!$B$7+Ayarlar!$B$8)-(G2*Ayarlar!$B$3+Ayarlar!$B$4+Ayarlar!$B$5))/(F2*(1-Ayarlar!$B$6))) | L2: =IF(G2="","GRAM EKSİK",IF(F2>30000,"FİYAT ŞÜPHELİ",IF(K2<0,"ZARARDA",IF(F2<I2,"RİSKLİ","ok")))) | M2: https://www.etsy.com/listing/1862428966
A3: chains | B3: 10K Gold Rope Chain Necklace – Twisted Diamond Cut, Men or W | C3: 1849022518 | D3: CR0P10-20 | E3: description | F3: 3974 | G3: 31.89 | H3: =IF(G3="","",G3*Ayarlar!$B$3+Ayarlar!$B$4+Ayarlar!$B$5) | I3: =IF(G3="","",ROUNDUP(((G3*Ayarlar!$B$3+Ayarlar!$B$4+Ayarlar!$B$5)+Ayarlar!$B$8)/((1-Ayarlar!$B$6)*(1-Ayarlar!$B$7)),0)) | J3: =IF(G3="","",ROUNDUP(((G3*Ayarlar!$B$3+Ayarlar!$B$4+Ayarlar!$B$5)+Ayarlar!$B$8)/((1-Ayarlar!$B$6)*(1-Ayarlar!$B$7-Ayarlar!$B$9)),0)) | K3: =IF(OR(G3="",F3=""),"",(F3*(1-Ayarlar!$B$6)-(F3*(1-Ayarlar!$B$6)*Ayarlar!$B$7+Ayarlar!$B$8)-(G3*Ayarlar!$B$3+Ayarlar!$B$4+Ayarlar!$B$5))/(F3*(1-Ayarlar!$B$6))) | L3: =IF(G3="","GRAM EKSİK",IF(F3>30000,"FİYAT ŞÜPHELİ",IF(K3<0,"ZARARDA",IF(F3<I3,"RİSKLİ","ok")))) | M3: https://www.etsy.com/listing/1849022518
A4: chains | B4: 10K Gold Rope Chain Necklace – Twisted Diamond Cut, Men or W | C4: 1849022518 | D4: CR0P10-22 | E4: description | F4: 4248 | G4: 35.08 | H4: =IF(G4="","",G4*Ayarlar!$B$3+Ayarlar!$B$4+Ayarlar!$B$5) | I4: =IF(G4="","",ROUNDUP(((G4*Ayarlar!$B$3+Ayarlar!$B$4+Ayarlar!$B$5)+Ayarlar!$B$8)/((1-Ayarlar!$B$6)*(1-Ayarlar!$B$7)),0)) | J4: =IF(G4="","",ROUNDUP(((G4*Ayarlar!$B$3+Ayarlar!$B$4+Ayarlar!$B$5)+Ayarlar!$B$8)/((1-Ayarlar!$B$6)*(1-Ayarlar!$B$7-Ayarlar!$B$9)),0)) | K4: =IF(OR(G4="",F4=""),"",(F4*(1-Ayarlar!$B$6)-(F4*(1-Ayarlar!$B$6)*Ayarlar!$B$7+Ayarlar!$B$8)-(G4*Ayarlar!$B$3+Ayarlar!$B$4+Ayarlar!$B$5))/(F4*(1-Ayarlar!$B$6))) | L4: =IF(G4="","GRAM EKSİK",IF(F4>30000,"FİYAT ŞÜPHELİ",IF(K4<0,"ZARARDA",IF(F4<I4,"RİSKLİ","ok")))) | M4: https://www.etsy.com/listing/1849022518
A5: chains | B5: 10K Gold Rope Chain Necklace – Twisted Diamond Cut, Men or W | C5: 1849022518 | D5: CR0P10-24 | E5: description | F5: 4524 | G5: 38.27 | H5: =IF(G5="","",G5*Ayarlar!$B$3+Ayarlar!$B$4+Ayarlar!$B$5) | I5: =IF(G5="","",ROUNDUP(((G5*Ayarlar!$B$3+Ayarlar!$B$4+Ayarlar!$B$5)+Ayarlar!$B$8)/((1-Ayarlar!$B$6)*(1-Ayarlar!$B$7)),0)) | J5: =IF(G5="","",ROUNDUP(((G5*Ayarlar!$B$3+Ayarlar!$B$4+Ayarlar!$B$5)+Ayarlar!$B$8)/((1-Ayarlar!$B$6)*(1-Ayarlar!$B$7-Ayarlar!$B$9)),0)) | K5: =IF(OR(G5="",F5=""),"",(F5*(1-Ayarlar!$B$6)-(F5*(1-Ayarlar!$B$6)*Ayarlar!$B$7+Ayarlar!$B$8)-(G5*Ayarlar!$B$3+Ayarlar!$B$4+Ayarlar!$B$5))/(F5*(1-Ayarlar!$B$6))) | L5: =IF(G5="","GRAM EKSİK",IF(F5>30000,"FİYAT ŞÜPHELİ",IF(K5<0,"ZARARDA",IF(F5<I5,"RİSKLİ","ok")))) | M5: https://www.etsy.com/listing/1849022518
A6: chains | B6: 10K Gold Rope Chain Necklace – Twisted Diamond Cut, Men or W | C6: 1849022518 | D6: CR0P10-26 | E6: description | F6: 4800 | G6: 41.46 | H6: =IF(G6="","",G6*Ayarlar!$B$3+Ayarlar!$B$4+Ayarlar!$B$5) | I6: =IF(G6="","",ROUNDUP(((G6*Ayarlar!$B$3+Ayarlar!$B$4+Ayarlar!$B$5)+Ayarlar!$B$8)/((1-Ayarlar!$B$6)*(1-Ayarlar!$B$7)),0)) | J6: =IF(G6="","",ROUNDUP(((G6*Ayarlar!$B$3+Ayarlar!$B$4+Ayarlar!$B$5)+Ayarlar!$B$8)/((1-Ayarlar!$B$6)*(1-Ayarlar!$B$7-Ayarlar!$B$9)),0)) | K6: =IF(OR(G6="",F6=""),"",(F6*(1-Ayarlar!$B$6)-(F6*(1-Ayarlar!$B$6)*Ayarlar!$B$7+Ayarlar!$B$8)-(G6*Ayarlar!$B$3+Ayarlar!$B$4+Ayarlar!$B$5))/(F6*(1-Ayarlar!$B$6))) | L6: =IF(G6="","GRAM EKSİK",IF(F6>30000,"FİYAT ŞÜPHELİ",IF(K6<0,"ZARARDA",IF(F6<I6,"RİSKLİ","ok")))) | M6: https://www.etsy.com/listing/1849022518
A7: chains | B7: 10K Gold Rope Chain Necklace – Twisted Diamond Cut, Men or W | C7: 1849022518 | D7: CR0P10-28 | E7: description | F7: 5075 | G7: 44.65 | H7: =IF(G7="","",G7*Ayarlar!$B$3+Ayarlar!$B$4+Ayarlar!$B$5) | I7: =IF(G7="","",ROUNDUP(((G7*Ayarlar!$B$3+Ayarlar!$B$4+Ayarlar!$B$5)+Ayarlar!$B$8)/((1-Ayarlar!$B$6)*(1-Ayarlar!$B$7)),0)) | J7: =IF(G7="","",ROUNDUP(((G7*Ayarlar!$B$3+Ayarlar!$B$4+Ayarlar!$B$5)+Ayarlar!$B$8)/((1-Ayarlar!$B$6)*(1-Ayarlar!$B$7-Ayarlar!$B$9)),0)) | K7: =IF(OR(G7="",F7=""),"",(F7*(1-Ayarlar!$B$6)-(F7*(1-Ayarlar!$B$6)*Ayarlar!$B$7+Ayarlar!$B$8)-(G7*Ayarlar!$B$3+Ayarlar!$B$4+Ayarlar!$B$5))/(F7*(1-Ayarlar!$B$6))) | L7: =IF(G7="","GRAM EKSİK",IF(F7>30000,"FİYAT ŞÜPHELİ",IF(K7<0,"ZARARDA",IF(F7<I7,"RİSKLİ","ok")))) | M7: https://www.etsy.com/listing/1849022518
A8: chains | B8: 10K Gold Rope Chain Necklace – Twisted Diamond Cut, Men or W | C8: 1849022518 | D8: CR0P6-20 | E8: description | F8: 1575 | G8: 14.78 | H8: =IF(G8="","",G8*Ayarlar!$B$3+Ayarlar!$B$4+Ayarlar!$B$5) | I8: =IF(G8="","",ROUNDUP(((G8*Ayarlar!$B$3+Ayarlar!$B$4+Ayarlar!$B$5)+Ayarlar!$B$8)/((1-Ayarlar!$B$6)*(1-Ayarlar!$B$7)),0)) | J8: =IF(G8="","",ROUNDUP(((G8*Ayarlar!$B$3+Ayarlar!$B$4+Ayarlar!$B$5)+Ayarlar!$B$8)/((1-Ayarlar!$B$6)*(1-Ayarlar!$B$7-Ayarlar!$B$9)),0)) | K8: =IF(OR(G8="",F8=""),"",(F8*(1-Ayarlar!$B$6)-(F8*(1-Ayarlar!$B$6)*Ayarlar!$B$7+Ayarlar!$B$8)-(G8*Ayarlar!$B$3+Ayarlar!$B$4+Ayarlar!$B$5))/(F8*(1-Ayarlar!$B$6))) | L8: =IF(G8="","GRAM EKSİK",IF(F8>30000,"FİYAT ŞÜPHELİ",IF(K8<0,"ZARARDA",IF(F8<I8,"RİSKLİ","ok")))) | M8: https://www.etsy.com/listing/1849022518
A9: chains | B9: 10K Gold Rope Chain Necklace – Twisted Diamond Cut, Men or W | C9: 1849022518 | D9: CR0P6-22 | E9: description | F9: 1755 | G9: 16.26 | H9: =IF(G9="","",G9*Ayarlar!$B$3+Ayarlar!$B$4+Ayarlar!$B$5) | I9: =IF(G9="","",ROUNDUP(((G9*Ayarlar!$B$3+Ayarlar!$B$4+Ayarlar!$B$5)+Ayarlar!$B$8)/((1-Ayarlar!$B$6)*(1-Ayarlar!$B$7)),0)) | J9: =IF(G9="","",ROUNDUP(((G9*Ayarlar!$B$3+Ayarlar!$B$4+Ayarlar!$B$5)+Ayarlar!$B$8)/((1-Ayarlar!$B$6)*(1-Ayarlar!$B$7-Ayarlar!$B$9)),0)) | K9: =IF(OR(G9="",F9=""),"",(F9*(1-Ayarlar!$B$6)-(F9*(1-Ayarlar!$B$6)*Ayarlar!$B$7+Ayarlar!$B$8)-(G9*Ayarlar!$B$3+Ayarlar!$B$4+Ayarlar!$B$5))/(F9*(1-Ayarlar!$B$6))) | L9: =IF(G9="","GRAM EKSİK",IF(F9>30000,"FİYAT ŞÜPHELİ",IF(K9<0,"ZARARDA",IF(F9<I9,"RİSKLİ","ok")))) | M9: https://www.etsy.com/listing/1849022518
A10: chains | B10: 10K Gold Rope Chain Necklace – Twisted Diamond Cut, Men or W | C10: 1849022518 | D10: CR0P6-24 | E10: description | F10: 1878 | G10: 17.74 | H10: =IF(G10="","",G10*Ayarlar!$B$3+Ayarlar!$B$4+Ayarlar!$B$5) | I10: =IF(G10="","",ROUNDUP(((G10*Ayarlar!$B$3+Ayarlar!$B$4+Ayarlar!$B$5)+Ayarlar!$B$8)/((1-Ayarlar!$B$6)*(1-Ayarlar!$B$7)),0)) | J10: =IF(G10="","",ROUNDUP(((G10*Ayarlar!$B$3+Ayarlar!$B$4+Ayarlar!$B$5)+Ayarlar!$B$8)/((1-Ayarlar!$B$6)*(1-Ayarlar!$B$7-Ayarlar!$B$9)),0)) | K10: =IF(OR(G10="",F10=""),"",(F10*(1-Ayarlar!$B$6)-(F10*(1-Ayarlar!$B$6)*Ayarlar!$B$7+Ayarlar!$B$8)-(G10*Ayarlar!$B$3+Ayarlar!$B$4+Ayarlar!$B$5))/(F10*(1-Ayarlar!$B$6))) | L10: =IF(G10="","GRAM EKSİK",IF(F10>30000,"FİYAT ŞÜPHELİ",IF(K10<0,"ZARARDA",IF(F10<I10,"RİSKLİ","ok")))) | M10: https://www.etsy.com/listing/1849022518
A11: chains | B11: 10K Gold Rope Chain Necklace – Twisted Diamond Cut, Men or W | C11: 1849022518 | D11: CR0P6-26 | E11: description | F11: 2002 | G11: 19.22 | H11: =IF(G11="","",G11*Ayarlar!$B$3+Ayarlar!$B$4+Ayarlar!$B$5) | I11: =IF(G11="","",ROUNDUP(((G11*Ayarlar!$B$3+Ayarlar!$B$4+Ayarlar!$B$5)+Ayarlar!$B$8)/((1-Ayarlar!$B$6)*(1-Ayarlar!$B$7)),0)) | J11: =IF(G11="","",ROUNDUP(((G11*Ayarlar!$B$3+Ayarlar!$B$4+Ayarlar!$B$5)+Ayarlar!$B$8)/((1-Ayarlar!$B$6)*(1-Ayarlar!$B$7-Ayarlar!$B$9)),0)) | K11: =IF(OR(G11="",F11=""),"",(F11*(1-Ayarlar!$B$6)-(F11*(1-Ayarlar!$B$6)*Ayarlar!$B$7+Ayarlar!$B$8)-(G11*Ayarlar!$B$3+Ayarlar!$B$4+Ayarlar!$B$5))/(F11*(1-Ayarlar!$B$6))) | L11: =IF(G11="","GRAM EKSİK",IF(F11>30000,"FİYAT ŞÜPHELİ",IF(K11<0,"ZARARDA",IF(F11<I11,"RİSKLİ","ok")))) | M11: https://www.etsy.com/listing/1849022518
A12: chains | B12: 10K Gold Rope Chain Necklace – Twisted Diamond Cut, Men or W | C12: 1849022518 | D12: CR0P6-28 | E12: description | F12: 2124 | G12: 20.69 | H12: =IF(G12="","",G12*Ayarlar!$B$3+Ayarlar!$B$4+Ayarlar!$B$5) | I12: =IF(G12="","",ROUNDUP(((G12*Ayarlar!$B$3+Ayarlar!$B$4+Ayarlar!$B$5)+Ayarlar!$B$8)/((1-Ayarlar!$B$6)*(1-Ayarlar!$B$7)),0)) | J12: =IF(G12="","",ROUNDUP(((G12*Ayarlar!$B$3+Ayarlar!$B$4+Ayarlar!$B$5)+Ayarlar!$B$8)/((1-Ayarlar!$B$6)*(1-Ayarlar!$B$7-Ayarlar!$B$9)),0)) | K12: =IF(OR(G12="",F12=""),"",(F12*(1-Ayarlar!$B$6)-(F12*(1-Ayarlar!$B$6)*Ayarlar!$B$7+Ayarlar!$B$8)-(G12*Ayarlar!$B$3+Ayarlar!$B$4+Ayarlar!$B$5))/(F12*(1-Ayarlar!$B$6))) | L12: =IF(G12="","GRAM EKSİK",IF(F12>30000,"FİYAT ŞÜPHELİ",IF(K12<0,"ZARARDA",IF(F12<I12,"RİSKLİ","ok")))) | M12: https://www.etsy.com/listing/1849022518
A13: chains | B13: 10K Gold Rope Chain Necklace – Twisted Diamond Cut, Men or W | C13: 1849022518 | D13: CR0P7-20 | E13: description | F13: 2231 | G13: 18.88 | H13: =IF(G13="","",G13*Ayarlar!$B$3+Ayarlar!$B$4+Ayarlar!$B$5) | I13: =IF(G13="","",ROUNDUP(((G13*Ayarlar!$B$3+Ayarlar!$B$4+Ayarlar!$B$5)+Ayarlar!$B$8)/((1-Ayarlar!$B$6)*(1-Ayarlar!$B$7)),0)) | J13: =IF(G13="","",ROUNDUP(((G13*Ayarlar!$B$3+Ayarlar!$B$4+Ayarlar!$B$5)+Ayarlar!$B$8)/((1-Ayarlar!$B$6)*(1-Ayarlar!$B$7-Ayarlar!$B$9)),0)) | K13: =IF(OR(G13="",F13=""),"",(F13*(1-Ayarlar!$B$6)-(F13*(1-Ayarlar!$B$6)*Ayarlar!$B$7+Ayarlar!$B$8)-(G13*Ayarlar!$B$3+Ayarlar!$B$4+Ayarlar!$B$5))/(F13*(1-Ayarlar!$B$6))) | L13: =IF(G13="","GRAM EKSİK",IF(F13>30000,"FİYAT ŞÜPHELİ",IF(K13<0,"ZARARDA",IF(F13<I13,"RİSKLİ","ok")))) | M13: https://www.etsy.com/listing/1849022518
A14: chains | B14: 10K Gold Rope Chain Necklace – Twisted Diamond Cut, Men or W | C14: 1849022518 | D14: CR0P7-22 | E14: description | F14: 2414 | G14: 20.77 | H14: =IF(G14="","",G14*Ayarlar!$B$3+Ayarlar!$B$4+Ayarlar!$B$5) | I14: =IF(G14="","",ROUNDUP(((G14*Ayarlar!$B$3+Ayarlar!$B$4+Ayarlar!$B$5)+Ayarlar!$B$8)/((1-Ayarlar!$B$6)*(1-Ayarlar!$B$7)),0)) | J14: =IF(G14="","",ROUNDUP(((G14*Ayarlar!$B$3+Ayarlar!$B$4+Ayarlar!$B$5)+Ayarlar!$B$8)/((1-Ayarlar!$B$6)*(1-Ayarlar!$B$7-Ayarlar!$B$9)),0)) | K14: =IF(OR(G14="",F14=""),"",(F14*(1-Ayarlar!$B$6)-(F14*(1-Ayarlar!$B$6)*Ayarlar!$B$7+Ayarlar!$B$8)-(G14*Ayarlar!$B$3+Ayarlar!$B$4+Ayarlar!$B$5))/(F14*(1-Ayarlar!$B$6))) | L14: =IF(G14="","GRAM EKSİK",IF(F14>30000,"FİYAT ŞÜPHELİ",IF(K14<0,"ZARARDA",IF(F14<I14,"RİSKLİ","ok")))) | M14: https://www.etsy.com/listing/1849022518
... A71: chains | B71: 10K Solid Gold Bead Ball Chain Necklace - Diamond Cut | C71: 1296858064 | D71: CMN4-24 | E71: description-scaled | F71: 4331 | G71: 33.93 | H71: =IF(G71="","",G71*Ayarlar!$B$3+Ayarlar!$B$4+Ayarlar!$B$5) | I71: =IF(G71="","",ROUNDUP(((G71*Ayarlar!$B$3+Ayarlar!$B$4+Ayarlar!$B$5)+Ayarlar!$B$8)/((1-Ayarlar!$B$6)*(1-Ayarlar!$B$7)),0)) | J71: =IF(G71="","",ROUNDUP(((G71*Ayarlar!$B$3+Ayarlar!$B$4+Ayarlar!$B$5)+Ayarlar!$B$8)/((1-Ayarlar!$B$6)*(1-Ayarlar!$B$7-Ayarlar!$B$9)),0)) | K71: =IF(OR(G71="",F71=""),"",(F71*(1-Ayarlar!$B$6)-(F71*(1-Ayarlar!$B$6)*Ayarlar!$B$7+Ayarlar!$B$8)-(G71*Ayarlar!$B$3+Ayarlar!$B$4+Ayarlar!$B$5))/(F71*(1-Ayarlar!$B$6))) | L71: =IF(G71="","GRAM EKSİK",IF(F71>30000,"FİYAT ŞÜPHELİ",IF(K71<0,"ZARARDA",IF(F71<I71,"RİSKLİ","ok")))) | M71: https://www.etsy.com/listing/1296858064
A72: chains | B72: 10K Solid Gold Herringbone Necklace, High Polish Snake Chain | C72: 1294201622 | D72: R1294201622 | E72: — | F72: 86.27 | H72: =IF(G72="","",G72*Ayarlar!$B$3+Ayarlar!$B$4+Ayarlar!$B$5) | I72: =IF(G72="","",ROUNDUP(((G72*Ayarlar!$B$3+Ayarlar!$B$4+Ayarlar!$B$5)+Ayarlar!$B$8)/((1-Ayarlar!$B$6)*(1-Ayarlar!$B$7)),0)) | J72: =IF(G72="","",ROUNDUP(((G72*Ayarlar!$B$3+Ayarlar!$B$4+Ayarlar!$B$5)+Ayarlar!$B$8)/((1-Ayarlar!$B$6)*(1-Ayarlar!$B$7-Ayarlar!$B$9)),0)) | K72: =IF(OR(G72="",F72=""),"",(F72*(1-Ayarlar!$B$6)-(F72*(1-Ayarlar!$B$6)*Ayarlar!$B$7+Ayarlar!$B$8)-(G72*Ayarlar!$B$3+Ayarlar!$B$4+Ayarlar!$B$5))/(F72*(1-Ayarlar!$B$6))) | L72: =IF(G72="","GRAM EKSİK",IF(F72>30000,"FİYAT ŞÜPHELİ",IF(K72<0,"ZARARDA",IF(F72<I72,"RİSKLİ","ok")))) | M72: https://www.etsy.com/listing/1294201622
A73: chains | B73: 10K White Gold Rope Bracelet – Unisex Solid Chain | C73: 4375720322 | D73: BWR2-7 | E73: description | F73: 421 | G73: 3.27 | H73: =IF(G73="","",G73*Ayarlar!$B$3+Ayarlar!$B$4+Ayarlar!$B$5) | I73: =IF(G73="","",ROUNDUP(((G73*Ayarlar!$B$3+Ayarlar!$B$4+Ayarlar!$B$5)+Ayarlar!$B$8)/((1-Ayarlar!$B$6)*(1-Ayarlar!$B$7)),0)) | J73: =IF(G73="","",ROUNDUP(((G73*Ayarlar!$B$3+Ayarlar!$B$4+Ayarlar!$B$5)+Ayarlar!$B$8)/((1-Ayarlar!$B$6)*(1-Ayarlar!$B$7-Ayarlar!$B$9)),0)) | K73: =IF(OR(G73="",F73=""),"",(F73*(1-Ayarlar!$B$6)-(F73*(1-Ayarlar!$B$6)*Ayarlar!$B$7+Ayarlar!$B$8)-(G73*Ayarlar!$B$3+Ayarlar!$B$4+Ayarlar!$B$5))/(F73*(1-Ayarlar!$B$6))) | L73: =IF(G73="","GRAM EKSİK",IF(F73>30000,"FİYAT ŞÜPHELİ",IF(K73<0,"ZARARDA",IF(F73<I73,"RİSKLİ","ok")))) | M73: https://www.etsy.com/listing/4375720322
A74: chains | B74: 10K White Gold Rope Bracelet – Unisex Solid Chain | C74: 4375720322 | D74: BWR2-7.5 | E74: description | F74: 451 | G74: 3.5 | H74: =IF(G74="","",G74*Ayarlar!$B$3+Ayarlar!$B$4+Ayarlar!$B$5) | I74: =IF(G74="","",ROUNDUP(((G74*Ayarlar!$B$3+Ayarlar!$B$4+Ayarlar!$B$5)+Ayarlar!$B$8)/((1-Ayarlar!$B$6)*(1-Ayarlar!$B$7)),0)) | J74: =IF(G74="","",ROUNDUP(((G74*Ayarlar!$B$3+Ayarlar!$B$4+Ayarlar!$B$5)+Ayarlar!$B$8)/((1-Ayarlar!$B$6)*(1-Ayarlar!$B$7-Ayarlar!$B$9)),0)) | K74: =IF(OR(G74="",F74=""),"",(F74*(1-Ayarlar!$B$6)-(F74*(1-Ayarlar!$B$6)*Ayarlar!$B$7+Ayarlar!$B$8)-(G74*Ayarlar!$B$3+Ayarlar!$B$4+Ayarlar!$B$5))/(F74*(1-Ayarlar!$B$6))) | L74: =IF(G74="","GRAM EKSİK",IF(F74>30000,"FİYAT ŞÜPHELİ",IF(K74<0,"ZARARDA",IF(F74<I74,"RİSKLİ","ok")))) | M74: https://www.etsy.com/listing/4375720322
A75: chains | B75: 10K White Gold Rope Bracelet – Unisex Solid Chain | C75: 4375720322 | D75: BWR2-8 | E75: description | F75: 481 | G75: 3.73 | H75: =IF(G75="","",G75*Ayarlar!$B$3+Ayarlar!$B$4+Ayarlar!$B$5) | I75: =IF(G75="","",ROUNDUP(((G75*Ayarlar!$B$3+Ayarlar!$B$4+Ayarlar!$B$5)+Ayarlar!$B$8)/((1-Ayarlar!$B$6)*(1-Ayarlar!$B$7)),0)) | J75: =IF(G75="","",ROUNDUP(((G75*Ayarlar!$B$3+Ayarlar!$B$4+Ayarlar!$B$5)+Ayarlar!$B$8)/((1-Ayarlar!$B$6)*(1-Ayarlar!$B$7-Ayarlar!$B$9)),0)) | K75: =IF(OR(G75="",F75=""),"",(F75*(1-Ayarlar!$B$6)-(F75*(1-Ayarlar!$B$6)*Ayarlar!$B$7+Ayarlar!$B$8)-(G75*Ayarlar!$B$3+Ayarlar!$B$4+Ayarlar!$B$5))/(F75*(1-Ayarlar!$B$6))) | L75: =IF(G75="","GRAM EKSİK",IF(F75>30000,"FİYAT ŞÜPHELİ",IF(K75<0,"ZARARDA",IF(F75<I75,"RİSKLİ","ok")))) | M75: https://www.etsy.com/listing/4375720322
A76: chains | B76: 10K White Gold Rope Bracelet – Unisex Solid Chain | C76: 4375720322 | D76: BWR2-8.5 | E76: description | F76: 511 | G76: 3.97 | H76: =IF(G76="","",G76*Ayarlar!$B$3+Ayarlar!$B$4+Ayarlar!$B$5) | I76: =IF(G76="","",ROUNDUP(((G76*Ayarlar!$B$3+Ayarlar!$B$4+Ayarlar!$B$5)+Ayarlar!$B$8)/((1-Ayarlar!$B$6)*(1-Ayarlar!$B$7)),0)) | J76: =IF(G76="","",ROUNDUP(((G76*Ayarlar!$B$3+Ayarlar!$B$4+Ayarlar!$B$5)+Ayarlar!$B$8)/((1-Ayarlar!$B$6)*(1-Ayarlar!$B$7-Ayarlar!$B$9)),0)) | K76: =IF(OR(G76="",F76=""),"",(F76*(1-Ayarlar!$B$6)-(F76*(1-Ayarlar!$B$6)*Ayarlar!$B$7+Ayarlar!$B$8)-(G76*Ayarlar!$B$3+Ayarlar!$B$4+Ayarlar!$B$5))/(F76*(1-Ayarlar!$B$6))) | L76: =IF(G76="","GRAM EKSİK",IF(F76>30000,"FİYAT ŞÜPHELİ",IF(K76<0,"ZARARDA",IF(F76<I76,"RİSKLİ","ok")))) | M76: https://www.etsy.com/listing/4375720322
A77: chains | B77: 10K White Gold Rope Bracelet – Unisex Solid Chain | C77: 4375720322 | D77: BWR3-7 | E77: description | F77: 655 | G77: 4.9 | H77: =IF(G77="","",G77*Ayarlar!$B$3+Ayarlar!$B$4+Ayarlar!$B$5) | I77: =IF(G77="","",ROUNDUP(((G77*Ayarlar!$B$3+Ayarlar!$B$4+Ayarlar!$B$5)+Ayarlar!$B$8)/((1-Ayarlar!$B$6)*(1-Ayarlar!$B$7)),0)) | J77: =IF(G77="","",ROUNDUP(((G77*Ayarlar!$B$3+Ayarlar!$B$4+Ayarlar!$B$5)+Ayarlar!$B$8)/((1-Ayarlar!$B$6)*(1-Ayarlar!$B$7-Ayarlar!$B$9)),0)) | K77: =IF(OR(G77="",F77=""),"",(F77*(1-Ayarlar!$B$6)-(F77*(1-Ayarlar!$B$6)*Ayarlar!$B$7+Ayarlar!$B$8)-(G77*Ayarlar!$B$3+Ayarlar!$B$4+Ayarlar!$B$5))/(F77*(1-Ayarlar!$B$6))) | L77: =IF(G77="","GRAM EKSİK",IF(F77>30000,"FİYAT ŞÜPHELİ",IF(K77<0,"ZARARDA",IF(F77<I77,"RİSKLİ","ok")))) | M77: https://www.etsy.com/listing/4375720322
A78: chains | B78: 10K White Gold Rope Bracelet – Unisex Solid Chain | C78: 4375720322 | D78: BWR3-7.5 | E78: description | F78: 696 | G78: 5.25 | H78: =IF(G78="","",G78*Ayarlar!$B$3+Ayarlar!$B$4+Ayarlar!$B$5) | I78: =IF(G78="","",ROUNDUP(((G78*Ayarlar!$B$3+Ayarlar!$B$4+Ayarlar!$B$5)+Ayarlar!$B$8)/((1-Ayarlar!$B$6)*(1-Ayarlar!$B$7)),0)) | J78: =IF(G78="","",ROUNDUP(((G78*Ayarlar!$B$3+Ayarlar!$B$4+Ayarlar!$B$5)+Ayarlar!$B$8)/((1-Ayarlar!$B$6)*(1-Ayarlar!$B$7-Ayarlar!$B$9)),0)) | K78: =IF(OR(G78="",F78=""),"",(F78*(1-Ayarlar!$B$6)-(F78*(1-Ayarlar!$B$6)*Ayarlar!$B$7+Ayarlar!$B$8)-(G78*Ayarlar!$B$3+Ayarlar!$B$4+Ayarlar!$B$5))/(F78*(1-Ayarlar!$B$6))) | L78: =IF(G78="","GRAM EKSİK",IF(F78>30000,"FİYAT ŞÜPHELİ",IF(K78<0,"ZARARDA",IF(F78<I78,"RİSKLİ","ok")))) | M78: https://www.etsy.com/listing/4375720322
A79: chains | B79: 10K White Gold Rope Bracelet – Unisex Solid Chain | C79: 4375720322 | D79: BWR3-8 | E79: description | F79: 746 | G79: 5.6 | H79: =IF(G79="","",G79*Ayarlar!$B$3+Ayarlar!$B$4+Ayarlar!$B$5) | I79: =IF(G79="","",ROUNDUP(((G79*Ayarlar!$B$3+Ayarlar!$B$4+Ayarlar!$B$5)+Ayarlar!$B$8)/((1-Ayarlar!$B$6)*(1-Ayarlar!$B$7)),0)) | J79: =IF(G79="","",ROUNDUP(((G79*Ayarlar!$B$3+Ayarlar!$B$4+Ayarlar!$B$5)+Ayarlar!$B$8)/((1-Ayarlar!$B$6)*(1-Ayarlar!$B$7-Ayarlar!$B$9)),0)) | K79: =IF(OR(G79="",F79=""),"",(F79*(1-Ayarlar!$B$6)-(F79*(1-Ayarlar!$B$6)*Ayarlar!$B$7+Ayarlar!$B$8)-(G79*Ayarlar!$B$3+Ayarlar!$B$4+Ayarlar!$B$5))/(F79*(1-Ayarlar!$B$6))) | L79: =IF(G79="","GRAM EKSİK",IF(F79>30000,"FİYAT ŞÜPHELİ",IF(K79<0,"ZARARDA",IF(F79<I79,"RİSKLİ","ok")))) | M79: https://www.etsy.com/listing/4375720322
A80: chains | B80: 10K White Gold Rope Bracelet – Unisex Solid Chain | C80: 4375720322 | D80: BWR3-8.5 | E80: description | F80: 793 | G80: 5.95 | H80: =IF(G80="","",G80*Ayarlar!$B$3+Ayarlar!$B$4+Ayarlar!$B$5) | I80: =IF(G80="","",ROUNDUP(((G80*Ayarlar!$B$3+Ayarlar!$B$4+Ayarlar!$B$5)+Ayarlar!$B$8)/((1-Ayarlar!$B$6)*(1-Ayarlar!$B$7)),0)) | J80: =IF(G80="","",ROUNDUP(((G80*Ayarlar!$B$3+Ayarlar!$B$4+Ayarlar!$B$5)+Ayarlar!$B$8)/((1-Ayarlar!$B$6)*(1-Ayarlar!$B$7-Ayarlar!$B$9)),0)) | K80: =IF(OR(G80="",F80=""),"",(F80*(1-Ayarlar!$B$6)-(F80*(1-Ayarlar!$B$6)*Ayarlar!$B$7+Ayarlar!$B$8)-(G80*Ayarlar!$B$3+Ayarlar!$B$4+Ayarlar!$B$5))/(F80*(1-Ayarlar!$B$6))) | L80: =IF(G80="","GRAM EKSİK",IF(F80>30000,"FİYAT ŞÜPHELİ",IF(K80<0,"ZARARDA",IF(F80<I80,"RİSKLİ","ok")))) | M80: https://www.etsy.com/listing/4375720322
A81: chains | B81: 10K White Gold Rope Bracelet – Unisex Solid Chain | C81: 4375720322 | D81: BWR32-7 | E81: description | F81: 828 | G81: 6.21 | H81: =IF(G81="","",G81*Ayarlar!$B$3+Ayarlar!$B$4+Ayarlar!$B$5) | I81: =IF(G81="","",ROUNDUP(((G81*Ayarlar!$B$3+Ayarlar!$B$4+Ayarlar!$B$5)+Ayarlar!$B$8)/((1-Ayarlar!$B$6)*(1-Ayarlar!$B$7)),0)) | J81: =IF(G81="","",ROUNDUP(((G81*Ayarlar!$B$3+Ayarlar!$B$4+Ayarlar!$B$5)+Ayarlar!$B$8)/((1-Ayarlar!$B$6)*(1-Ayarlar!$B$7-Ayarlar!$B$9)),0)) | K81: =IF(OR(G81="",F81=""),"",(F81*(1-Ayarlar!$B$6)-(F81*(1-Ayarlar!$B$6)*Ayarlar!$B$7+Ayarlar!$B$8)-(G81*Ayarlar!$B$3+Ayarlar!$B$4+Ayarlar!$B$5))/(F81*(1-Ayarlar!$B$6))) | L81: =IF(G81="","GRAM EKSİK",IF(F81>30000,"FİYAT ŞÜPHELİ",IF(K81<0,"ZARARDA",IF(F81<I81,"RİSKLİ","ok")))) | M81: https://www.etsy.com/listing/4375720322
A82: chains | B82: 10K White Gold Rope Bracelet – Unisex Solid Chain | C82: 4375720322 | D82: BWR32-7.5 | E82: description | F82: 888 | G82: 6.66 | H82: =IF(G82="","",G82*Ayarlar!$B$3+Ayarlar!$B$4+Ayarlar!$B$5) | I82: =IF(G82="","",ROUNDUP(((G82*Ayarlar!$B$3+Ayarlar!$B$4+Ayarlar!$B$5)+Ayarlar!$B$8)/((1-Ayarlar!$B$6)*(1-Ayarlar!$B$7)),0)) | J82: =IF(G82="","",ROUNDUP(((G82*Ayarlar!$B$3+Ayarlar!$B$4+Ayarlar!$B$5)+Ayarlar!$B$8)/((1-Ayarlar!$B$6)*(1-Ayarlar!$B$7-Ayarlar!$B$9)),0)) | K82: =IF(OR(G82="",F82=""),"",(F82*(1-Ayarlar!$B$6)-(F82*(1-Ayarlar!$B$6)*Ayarlar!$B$7+Ayarlar!$B$8)-(G82*Ayarlar!$B$3+Ayarlar!$B$4+Ayarlar!$B$5))/(F82*(1-Ayarlar!$B$6))) | L82: =IF(G82="","GRAM EKSİK",IF(F82>30000,"FİYAT ŞÜPHELİ",IF(K82<0,"ZARARDA",IF(F82<I82,"RİSKLİ","ok")))) | M82: https://www.etsy.com/listing/4375720322
A83: chains | B83: 10K White Gold Rope Bracelet – Unisex Solid Chain | C83: 4375720322 | D83: BWR32-8 | E83: description | F83: 949 | G83: 7.1 | H83: =IF(G83="","",G83*Ayarlar!$B$3+Ayarlar!$B$4+Ayarlar!$B$5) | I83: =IF(G83="","",ROUNDUP(((G83*Ayarlar!$B$3+Ayarlar!$B$4+Ayarlar!$B$5)+Ayarlar!$B$8)/((1-Ayarlar!$B$6)*(1-Ayarlar!$B$7)),0)) | J83: =IF(G83="","",ROUNDUP(((G83*Ayarlar!$B$3+Ayarlar!$B$4+Ayarlar!$B$5)+Ayarlar!$B$8)/((1-Ayarlar!$B$6)*(1-Ayarlar!$B$7-Ayarlar!$B$9)),0)) | K83: =IF(OR(G83="",F83=""),"",(F83*(1-Ayarlar!$B$6)-(F83*(1-Ayarlar!$B$6)*Ayarlar!$B$7+Ayarlar!$B$8)-(G83*Ayarlar!$B$3+Ayarlar!$B$4+Ayarlar!$B$5))/(F83*(1-Ayarlar!$B$6))) | L83: =IF(G83="","GRAM EKSİK",IF(F83>30000,"FİYAT ŞÜPHELİ",IF(K83<0,"ZARARDA",IF(F83<I83,"RİSKLİ","ok")))) | M83: https://www.etsy.com/listing/4375720322
A84: chains | B84: 10K White Gold Rope Bracelet – Unisex Solid Chain | C84: 4375720322 | D84: BWR32-8.5 | E84: description | F84: 1009 | G84: 7.54 | H84: =IF(G84="","",G84*Ayarlar!$B$3+Ayarlar!$B$4+Ayarlar!$B$5) | I84: =IF(G84="","",ROUNDUP(((G84*Ayarlar!$B$3+Ayarlar!$B$4+Ayarlar!$B$5)+Ayarlar!$B$8)/((1-Ayarlar!$B$6)*(1-Ayarlar!$B$7)),0)) | J84: =IF(G84="","",ROUNDUP(((G84*Ayarlar!$B$3+Ayarlar!$B$4+Ayarlar!$B$5)+Ayarlar!$B$8)/((1-Ayarlar!$B$6)*(1-Ayarlar!$B$7-Ayarlar!$B$9)),0)) | K84: =IF(OR(G84="",F84=""),"",(F84*(1-Ayarlar!$B$6)-(F84*(1-Ayarlar!$B$6)*Ayarlar!$B$7+Ayarlar!$B$8)-(G84*Ayarlar!$B$3+Ayarlar!$B$4+Ayarlar!$B$5))/(F84*(1-Ayarlar!$B$6))) | L84: =IF(G84="","GRAM EKSİK",IF(F84>30000,"FİYAT ŞÜPHELİ",IF(K84<0,"ZARARDA",IF(F84<I84,"RİSKLİ","ok")))) | M84: https://www.etsy.com/listing/4375720322
... A145: chains | B145: 14K Gold Bracelet, Round Box Chain Design in Yellow | C145: 1863553142 | D145: BWRD5-8 | E145: manual | F145: 1118 | G145: 6.9 | H145: =IF(G145="","",G145*Ayarlar!$B$3+Ayarlar!$B$4+Ayarlar!$B$5) | I145: =IF(G145="","",ROUNDUP(((G145*Ayarlar!$B$3+Ayarlar!$B$4+Ayarlar!$B$5)+Ayarlar!$B$8)/((1-Ayarlar!$B$6)*(1-Ayarlar!$B$7)),0)) | J145: =IF(G145="","",ROUNDUP(((G145*Ayarlar!$B$3+Ayarlar!$B$4+Ayarlar!$B$5)+Ayarlar!$B$8)/((1-Ayarlar!$B$6)*(1-Ayarlar!$B$7-Ayarlar!$B$9)),0)) | K145: =IF(OR(G145="",F145=""),"",(F145*(1-Ayarlar!$B$6)-(F145*(1-Ayarlar!$B$6)*Ayarlar!$B$7+Ayarlar!$B$8)-(G145*Ayarlar!$B$3+Ayarlar!$B$4+Ayarlar!$B$5))/(F145*(1-Ayarlar!$B$6))) | L145: =IF(G145="","GRAM EKSİK",IF(F145>30000,"FİYAT ŞÜPHELİ",IF(K145<0,"ZARARDA",IF(F145<I145,"RİSKLİ","ok")))) | M145: https://www.etsy.com/listing/1863553142
A146: chains | B146: 14K Gold Necklace, Solid White Bead Ball Chain Design | C146: 4546907749 | D146: CWM42F-16 | E146: — | F146: 812.7 | H146: =IF(G146="","",G146*Ayarlar!$B$3+Ayarlar!$B$4+Ayarlar!$B$5) | I146: =IF(G146="","",ROUNDUP(((G146*Ayarlar!$B$3+Ayarlar!$B$4+Ayarlar!$B$5)+Ayarlar!$B$8)/((1-Ayarlar!$B$6)*(1-Ayarlar!$B$7)),0)) | J146: =IF(G146="","",ROUNDUP(((G146*Ayarlar!$B$3+Ayarlar!$B$4+Ayarlar!$B$5)+Ayarlar!$B$8)/((1-Ayarlar!$B$6)*(1-Ayarlar!$B$7-Ayarlar!$B$9)),0)) | K146: =IF(OR(G146="",F146=""),"",(F146*(1-Ayarlar!$B$6)-(F146*(1-Ayarlar!$B$6)*Ayarlar!$B$7+Ayarlar!$B$8)-(G146*Ayarlar!$B$3+Ayarlar!$B$4+Ayarlar!$B$5))/(F146*(1-Ayarlar!$B$6))) | L146: =IF(G146="","GRAM EKSİK",IF(F146>30000,"FİYAT ŞÜPHELİ",IF(K146<0,"ZARARDA",IF(F146<I146,"RİSKLİ","ok")))) | M146: https://www.etsy.com/listing/4546907749
A147: chains | B147: 14K Gold Necklace, Solid White Bead Ball Chain Design | C147: 4546907749 | D147: CWM42F-18 | E147: — | F147: 914.28 | H147: =IF(G147="","",G147*Ayarlar!$B$3+Ayarlar!$B$4+Ayarlar!$B$5) | I147: =IF(G147="","",ROUNDUP(((G147*Ayarlar!$B$3+Ayarlar!$B$4+Ayarlar!$B$5)+Ayarlar!$B$8)/((1-Ayarlar!$B$6)*(1-Ayarlar!$B$7)),0)) | J147: =IF(G147="","",ROUNDUP(((G147*Ayarlar!$B$3+Ayarlar!$B$4+Ayarlar!$B$5)+Ayarlar!$B$8)/((1-Ayarlar!$B$6)*(1-Ayarlar!$B$7-Ayarlar!$B$9)),0)) | K147: =IF(OR(G147="",F147=""),"",(F147*(1-Ayarlar!$B$6)-(F147*(1-Ayarlar!$B$6)*Ayarlar!$B$7+Ayarlar!$B$8)-(G147*Ayarlar!$B$3+Ayarlar!$B$4+Ayarlar!$B$5))/(F147*(1-Ayarlar!$B$6))) | L147: =IF(G147="","GRAM EKSİK",IF(F147>30000,"FİYAT ŞÜPHELİ",IF(K147<0,"ZARARDA",IF(F147<I147,"RİSKLİ","ok")))) | M147: https://www.etsy.com/listing/4546907749
A148: chains | B148: 14K Gold Necklace, Solid White Bead Ball Chain Design | C148: 4546907749 | D148: CWM42F-20 | E148: — | F148: 1015.87 | H148: =IF(G148="","",G148*Ayarlar!$B$3+Ayarlar!$B$4+Ayarlar!$B$5) | I148: =IF(G148="","",ROUNDUP(((G148*Ayarlar!$B$3+Ayarlar!$B$4+Ayarlar!$B$5)+Ayarlar!$B$8)/((1-Ayarlar!$B$6)*(1-Ayarlar!$B$7)),0)) | J148: =IF(G148="","",ROUNDUP(((G148*Ayarlar!$B$3+Ayarlar!$B$4+Ayarlar!$B$5)+Ayarlar!$B$8)/((1-Ayarlar!$B$6)*(1-Ayarlar!$B$7-Ayarlar!$B$9)),0)) | K148: =IF(OR(G148="",F148=""),"",(F148*(1-Ayarlar!$B$6)-(F148*(1-Ayarlar!$B$6)*Ayarlar!$B$7+Ayarlar!$B$8)-(G148*Ayarlar!$B$3+Ayarlar!$B$4+Ayarlar!$B$5))/(F148*(1-Ayarlar!$B$6))) | L148: =IF(G148="","GRAM EKSİK",IF(F148>30000,"FİYAT ŞÜPHELİ",IF(K148<0,"ZARARDA",IF(F148<I148,"RİSKLİ","ok")))) | M148: https://www.etsy.com/listing/4546907749
A149: chains | B149: 14K Gold Necklace, Solid White Bead Ball Chain Design | C149: 4546907749 | D149: CWM42F-22 | E149: — | F149: 1117.46 | H149: =IF(G149="","",G149*Ayarlar!$B$3+Ayarlar!$B$4+Ayarlar!$B$5) | I149: =IF(G149="","",ROUNDUP(((G149*Ayarlar!$B$3+Ayarlar!$B$4+Ayarlar!$B$5)+Ayarlar!$B$8)/((1-Ayarlar!$B$6)*(1-Ayarlar!$B$7)),0)) | J149: =IF(G149="","",ROUNDUP(((G149*Ayarlar!$B$3+Ayarlar!$B$4+Ayarlar!$B$5)+Ayarlar!$B$8)/((1-Ayarlar!$B$6)*(1-Ayarlar!$B$7-Ayarlar!$B$9)),0)) | K149: =IF(OR(G149="",F149=""),"",(F149*(1-Ayarlar!$B$6)-(F149*(1-Ayarlar!$B$6)*Ayarlar!$B$7+Ayarlar!$B$8)-(G149*Ayarlar!$B$3+Ayarlar!$B$4+Ayarlar!$B$5))/(F149*(1-Ayarlar!$B$6))) | L149: =IF(G149="","GRAM EKSİK",IF(F149>30000,"FİYAT ŞÜPHELİ",IF(K149<0,"ZARARDA",IF(F149<I149,"RİSKLİ","ok")))) | M149: https://www.etsy.com/listing/4546907749
A150: chains | B150: 14K Gold Necklace, Solid White Bead Ball Chain Design | C150: 4546907749 | D150: CWM42F-24 | E150: — | F150: 1219.05 | H150: =IF(G150="","",G150*Ayarlar!$B$3+Ayarlar!$B$4+Ayarlar!$B$5) | I150: =IF(G150="","",ROUNDUP(((G150*Ayarlar!$B$3+Ayarlar!$B$4+Ayarlar!$B$5)+Ayarlar!$B$8)/((1-Ayarlar!$B$6)*(1-Ayarlar!$B$7)),0)) | J150: =IF(G150="","",ROUNDUP(((G150*Ayarlar!$B$3+Ayarlar!$B$4+Ayarlar!$B$5)+Ayarlar!$B$8)/((1-Ayarlar!$B$6)*(1-Ayarlar!$B$7-Ayarlar!$B$9)),0)) | K150: =IF(OR(G150="",F150=""),"",(F150*(1-Ayarlar!$B$6)-(F150*(1-Ayarlar!$B$6)*Ayarlar!$B$7+Ayarlar!$B$8)-(G150*Ayarlar!$B$3+Ayarlar!$B$4+Ayarlar!$B$5))/(F150*(1-Ayarlar!$B$6))) | L150: =IF(G150="","GRAM EKSİK",IF(F150>30000,"FİYAT ŞÜPHELİ",IF(K150<0,"ZARARDA",IF(F150<I150,"RİSKLİ","ok")))) | M150: https://www.etsy.com/listing/4546907749
A151: chains | B151: 14K Gold Necklace, Solid White Bead Ball Chain Design | C151: 4546907749 | D151: CWM43F-16 | E151: — | F151: 1741.5 | H151: =IF(G151="","",G151*Ayarlar!$B$3+Ayarlar!$B$4+Ayarlar!$B$5) | I151: =IF(G151="","",ROUNDUP(((G151*Ayarlar!$B$3+Ayarlar!$B$4+Ayarlar!$B$5)+Ayarlar!$B$8)/((1-Ayarlar!$B$6)*(1-Ayarlar!$B$7)),0)) | J151: =IF(G151="","",ROUNDUP(((G151*Ayarlar!$B$3+Ayarlar!$B$4+Ayarlar!$B$5)+Ayarlar!$B$8)/((1-Ayarlar!$B$6)*(1-Ayarlar!$B$7-Ayarlar!$B$9)),0)) | K151: =IF(OR(G151="",F151=""),"",(F151*(1-Ayarlar!$B$6)-(F151*(1-Ayarlar!$B$6)*Ayarlar!$B$7+Ayarlar!$B$8)-(G151*Ayarlar!$B$3+Ayarlar!$B$4+Ayarlar!$B$5))/(F151*(1-Ayarlar!$B$6))) | L151: =IF(G151="","GRAM EKSİK",IF(F151>30000,"FİYAT ŞÜPHELİ",IF(K151<0,"ZARARDA",IF(F151<I151,"RİSKLİ","ok")))) | M151: https://www.etsy.com/listing/4546907749
A152: chains | B152: 14K Gold Necklace, Solid White Bead Ball Chain Design | C152: 4546907749 | D152: CWM43F-18 | E152: — | F152: 1950.48 | H152: =IF(G152="","",G152*Ayarlar!$B$3+Ayarlar!$B$4+Ayarlar!$B$5) | I152: =IF(G152="","",ROUNDUP(((G152*Ayarlar!$B$3+Ayarlar!$B$4+Ayarlar!$B$5)+Ayarlar!$B$8)/((1-Ayarlar!$B$6)*(1-Ayarlar!$B$7)),0)) | J152: =IF(G152="","",ROUNDUP(((G152*Ayarlar!$B$3+Ayarlar!$B$4+Ayarlar!$B$5)+Ayarlar!$B$8)/((1-Ayarlar!$B$6)*(1-Ayarlar!$B$7-Ayarlar!$B$9)),0)) | K152: =IF(OR(G152="",F152=""),"",(F152*(1-Ayarlar!$B$6)-(F152*(1-Ayarlar!$B$6)*Ayarlar!$B$7+Ayarlar!$B$8)-(G152*Ayarlar!$B$3+Ayarlar!$B$4+Ayarlar!$B$5))/(F152*(1-Ayarlar!$B$6))) | L152: =IF(G152="","GRAM EKSİK",IF(F152>30000,"FİYAT ŞÜPHELİ",IF(K152<0,"ZARARDA",IF(F152<I152,"RİSKLİ","ok")))) | M152: https://www.etsy.com/listing/4546907749
A153: chains | B153: 14K Gold Necklace, Solid White Bead Ball Chain Design | C153: 4546907749 | D153: CWM43F-20 | E153: — | F153: 2147.85 | H153: =IF(G153="","",G153*Ayarlar!$B$3+Ayarlar!$B$4+Ayarlar!$B$5) | I153: =IF(G153="","",ROUNDUP(((G153*Ayarlar!$B$3+Ayarlar!$B$4+Ayarlar!$B$5)+Ayarlar!$B$8)/((1-Ayarlar!$B$6)*(1-Ayarlar!$B$7)),0)) | J153: =IF(G153="","",ROUNDUP(((G153*Ayarlar!$B$3+Ayarlar!$B$4+Ayarlar!$B$5)+Ayarlar!$B$8)/((1-Ayarlar!$B$6)*(1-Ayarlar!$B$7-Ayarlar!$B$9)),0)) | K153: =IF(OR(G153="",F153=""),"",(F153*(1-Ayarlar!$B$6)-(F153*(1-Ayarlar!$B$6)*Ayarlar!$B$7+Ayarlar!$B$8)-(G153*Ayarlar!$B$3+Ayarlar!$B$4+Ayarlar!$B$5))/(F153*(1-Ayarlar!$B$6))) | L153: =IF(G153="","GRAM EKSİK",IF(F153>30000,"FİYAT ŞÜPHELİ",IF(K153<0,"ZARARDA",IF(F153<I153,"RİSKLİ","ok")))) | M153: https://www.etsy.com/listing/4546907749
A154: chains | B154: 14K Gold Necklace, Solid White Bead Ball Chain Design | C154: 4546907749 | D154: CWM43F-22 | E154: — | F154: 2322 | H154: =IF(G154="","",G154*Ayarlar!$B$3+Ayarlar!$B$4+Ayarlar!$B$5) | I154: =IF(G154="","",ROUNDUP(((G154*Ayarlar!$B$3+Ayarlar!$B$4+Ayarlar!$B$5)+Ayarlar!$B$8)/((1-Ayarlar!$B$6)*(1-Ayarlar!$B$7)),0)) | J154: =IF(G154="","",ROUNDUP(((G154*Ayarlar!$B$3+Ayarlar!$B$4+Ayarlar!$B$5)+Ayarlar!$B$8)/((1-Ayarlar!$B$6)*(1-Ayarlar!$B$7-Ayarlar!$B$9)),0)) | K154: =IF(OR(G154="",F154=""),"",(F154*(1-Ayarlar!$B$6)-(F154*(1-Ayarlar!$B$6)*Ayarlar!$B$7+Ayarlar!$B$8)-(G154*Ayarlar!$B$3+Ayarlar!$B$4+Ayarlar!$B$5))/(F154*(1-Ayarlar!$B$6))) | L154: =IF(G154="","GRAM EKSİK",IF(F154>30000,"FİYAT ŞÜPHELİ",IF(K154<0,"ZARARDA",IF(F154<I154,"RİSKLİ","ok")))) | M154: https://www.etsy.com/listing/4546907749
A155: chains | B155: 14K Gold Necklace, Solid White Bead Ball Chain Design | C155: 4546907749 | D155: CWM43F-24 | E155: — | F155: 2554.2 | H155: =IF(G155="","",G155*Ayarlar!$B$3+Ayarlar!$B$4+Ayarlar!$B$5) | I155: =IF(G155="","",ROUNDUP(((G155*Ayarlar!$B$3+Ayarlar!$B$4+Ayarlar!$B$5)+Ayarlar!$B$8)/((1-Ayarlar!$B$6)*(1-Ayarlar!$B$7)),0)) | J155: =IF(G155="","",ROUNDUP(((G155*Ayarlar!$B$3+Ayarlar!$B$4+Ayarlar!$B$5)+Ayarlar!$B$8)/((1-Ayarlar!$B$6)*(1-Ayarlar!$B$7-Ayarlar!$B$9)),0)) | K155: =IF(OR(G155="",F155=""),"",(F155*(1-Ayarlar!$B$6)-(F155*(1-Ayarlar!$B$6)*Ayarlar!$B$7+Ayarlar!$B$8)-(G155*Ayarlar!$B$3+Ayarlar!$B$4+Ayarlar!$B$5))/(F155*(1-Ayarlar!$B$6))) | L155: =IF(G155="","GRAM EKSİK",IF(F155>30000,"FİYAT ŞÜPHELİ",IF(K155<0,"ZARARDA",IF(F155<I155,"RİSKLİ","ok")))) | M155: https://www.etsy.com/listing/4546907749
A156: chains | B156: 14K Gold Necklace, Solid White Bead Ball Chain Design | C156: 4546907749 | D156: CWM44F-16 | E156: — | F156: 2902.5 | H156: =IF(G156="","",G156*Ayarlar!$B$3+Ayarlar!$B$4+Ayarlar!$B$5) | I156: =IF(G156="","",ROUNDUP(((G156*Ayarlar!$B$3+Ayarlar!$B$4+Ayarlar!$B$5)+Ayarlar!$B$8)/((1-Ayarlar!$B$6)*(1-Ayarlar!$B$7)),0)) | J156: =IF(G156="","",ROUNDUP(((G156*Ayarlar!$B$3+Ayarlar!$B$4+Ayarlar!$B$5)+Ayarlar!$B$8)/((1-Ayarlar!$B$6)*(1-Ayarlar!$B$7-Ayarlar!$B$9)),0)) | K156: =IF(OR(G156="",F156=""),"",(F156*(1-Ayarlar!$B$6)-(F156*(1-Ayarlar!$B$6)*Ayarlar!$B$7+Ayarlar!$B$8)-(G156*Ayarlar!$B$3+Ayarlar!$B$4+Ayarlar!$B$5))/(F156*(1-Ayarlar!$B$6))) | L156: =IF(G156="","GRAM EKSİK",IF(F156>30000,"FİYAT ŞÜPHELİ",IF(K156<0,"ZARARDA",IF(F156<I156,"RİSKLİ","ok")))) | M156: https://www.etsy.com/listing/4546907749
...

Sheet Listing Özeti
A1: Bölüm | B1: Listing | C1: Etsy ID | D1: Varyant | E1: Gramsız | F1: Min Fiyat $ | G1: Max Fiyat $ | H1: Durum | I1: Etsy Linki
A2: legacy | B2: Solid 14K Yellow Gold Miami Cuban Link Chain Necklace, Heavy | C2: 1615728651 | D2: 45 | E2: 35 | F2: 430 | G2: 49999.99 | H2: kısmen eksik | I2: https://www.etsy.com/listing/1615728651
A3: legacy | B3: 14K Real Gold Mariner Link Chain / Puffed Anchor Necklace | C3: 1390701590 | D3: 30 | E3: 20 | F3: 1941.5 | G3: 7729 | H3: kısmen eksik | I3: https://www.etsy.com/listing/1390701590
A4: legacy | B4: 14K Gold Two-Tone Pave Curb Cuban Bracelet | C4: 1877707029 | D4: 30 | E4: 17 | F4: 542 | G4: 3607 | H4: kısmen eksik | I4: https://www.etsy.com/listing/1877707029
A5: chains | B5: 14K Gold Necklace, Solid White Bead Ball Chain Design | C5: 4546907749 | D5: 15 | E5: 15 | F5: 812.7 | G5: 4295.7 | H5: TÜMÜ EKSİK | I5: https://www.etsy.com/listing/4546907749
A6: legacy | B6: Ice Out Bracelet in 10K Gold, Two Tone Diamond Cut Link | C6: 1363498864 | D6: 12 | E6: 6 | F6: 532 | G6: 1300 | H6: kısmen eksik | I6: https://www.etsy.com/listing/1363498864
A7: earrings | B7: 10K Yellow Gold Hoop Earrings, Diamond Cut, All Sizes | C7: 1225508465 | D7: 7 | E7: 3 | F7: 155.87 | G7: 505.25 | H7: kısmen eksik | I7: https://www.etsy.com/listing/1225508465
A8: protection | B8: 10K Gold Italian Horn Cornicello Pendant Necklace / Miami Cu | C8: 1435050061 | D8: 18 | E8: 3 | F8: 78.35 | G8: 573 | H8: kısmen eksik | I8: https://www.etsy.com/listing/1435050061
A9: chains | B9: Chunky 14K Yellow Gold Rope Bracelet / Unisex Statement Jewe | C9: 4296776011 | D9: 12 | E9: 2 | F9: 1431 | G9: 2031.75 | H9: kısmen eksik | I9: https://www.etsy.com/listing/4296776011
A10: earrings | B10: 10K Solid Gold Nugget Stud Earrings, Diamond Cut | C10: 1475151914 | D10: 4 | E10: 2 | F10: 145 | G10: 418 | H10: kısmen eksik | I10: https://www.etsy.com/listing/1475151914
A11: legacy | B11: 10K Real Yellow Gold Miami Cuban Link Bracelet - Unisex | C11: 1195581074 | D11: 27 | E11: 2 | F11: 158 | G11: 2918 | H11: kısmen eksik | I11: https://www.etsy.com/listing/1195581074
A12: legacy | B12: Real 14K Gold Miami Cuban Link Bracelet - Unisex Chain Jewel | C12: 4320364926 | D12: 21 | E12: 2 | F12: 195 | G12: 3634 | H12: kısmen eksik | I12: https://www.etsy.com/listing/4320364926
A13: protection | B13: 14K Gold Cornicello Necklace, Miami Cuban Chain, Italian Hor | C13: 1537611621 | D13: 48 | E13: 2 | F13: 116.1 | G13: 8192 | H13: kısmen eksik | I13: https://www.etsy.com/listing/1537611621
... A114: rings | B114: Dainty 925 Sterling Silver Tennis Bracelet, Round CZ Stone, | C114: 1454572095 | D114: 6 | E114: 0 | F114: 34.39 | G114: 38.69 | H114: tam | I114: https://www.etsy.com/listing/1454572095
